<?xml version="1.0" encoding="utf-8"?>
<!-- This URDF was automatically created by SolidWorks to URDF Exporter! Originally created by Stephen Brawner (brawner@gmail.com) 
     Commit Version: 1.6.0-4-g7f85cfe  Build Version: 1.6.7995.38578
     For more information, please see http://wiki.ros.org/sw_urdf_exporter -->
<robot
  name="fullurdf2">
  <link
    name="base_link">
    <inertial>
      <origin
        xyz="2.27682456221956E-18 -0.005 0"
        rpy="0 0 0" />
      <mass
        value="0.0002" />
      <inertia
        ixx="3.33333333333334E-09"
        ixy="1.72329294281881E-26"
        ixz="3.0309750528515E-26"
        iyy="1.73333333333333E-09"
        iyz="-8.32068698519475E-26"
        izz="1.73333333333333E-09" />
    </inertial>
    <visual>
      <origin
        xyz="0 0 0"
        rpy="0 0 0" />
      <geometry>
        <mesh
          filename="package://fullurdf2/meshes/base_link.STL" />
      </geometry>
      <material
        name="">
        <color
          rgba="0.792156862745098 0.819607843137255 0.933333333333333 1" />
      </material>
    </visual>
    <collision>
      <origin
        xyz="0 0 0"
        rpy="0 0 0" />
      <geometry>
        <mesh
          filename="package://fullurdf2/meshes/base_link.STL" />
      </geometry>
    </collision>
  </link>
  <link
    name="sec01">
    <inertial>
      <origin
        xyz="7.58941520739853E-19 0 0"
        rpy="0 0 0" />
      <mass
        value="0.0139800873084746" />
      <inertia
        ixx="3.7862736460452E-07"
        ixy="4.21411460173609E-39"
        ixz="1.77231475113485E-55"
        iyy="6.99004365423729E-07"
        iyz="6.75401820523941E-40"
        izz="3.7862736460452E-07" />
    </inertial>
    <visual>
      <origin
        xyz="0 0 0"
        rpy="0 0 0" />
      <geometry>
        <mesh
          filename="package://fullurdf2/meshes/sec01.STL" />
      </geometry>
      <material
        name="">
        <color
          rgba="0.537254901960784 0.349019607843137 0.337254901960784 1" />
      </material>
    </visual>
    <collision>
      <origin
        xyz="0 0 0"
        rpy="0 0 0" />
      <geometry>
        <mesh
          filename="package://fullurdf2/meshes/sec01.STL" />
      </geometry>
    </collision>
  </link>
  <joint
    name="joint01"
    type="fixed">
    <origin
      xyz="0 0 0"
      rpy="0 0 0" />
    <parent
      link="base_link" />
    <child
      link="sec01" />
    <axis
      xyz="0 0 0" />
	<dynamics damping="0.00001" friction="0.1"/>
    <limit
      lower="-1.571"
      upper="1.571"
      effort="100"
      velocity="500" />
  </joint>
  <link
    name="sec02">
    <inertial>
      <origin
        xyz="4.33680868994202E-19 0 0"
        rpy="0 0 0" />
      <mass
        value="0.0139800873084746" />
      <inertia
        ixx="3.7862736460452E-07"
        ixy="4.90793830114796E-24"
        ixz="-9.81587660229593E-24"
        iyy="6.99004365423729E-07"
        iyz="-1.22698457528699E-24"
        izz="3.7862736460452E-07" />
    </inertial>
    <visual>
      <origin
        xyz="0 0 0"
        rpy="0 0 0" />
      <geometry>
        <mesh
          filename="package://fullurdf2/meshes/sec02.STL" />
      </geometry>
      <material
        name="">
        <color
          rgba="0.537254901960784 0.349019607843137 0.337254901960784 1" />
      </material>
    </visual>
    <collision>
      <origin
        xyz="0 0 0"
        rpy="0 0 0" />
      <geometry>
        <mesh
          filename="package://fullurdf2/meshes/sec02.STL" />
      </geometry>
    </collision>
  </link>
  <joint
    name="joint02"
    type="revolute">
    <origin
      xyz="0 0.01 0"
      rpy="0 0 0" />
    <parent
      link="sec01" />
    <child
      link="sec02" />
    <axis
      xyz="1 0 0" />
	<dynamics damping="0.00001" friction="0.1"/>
    <limit
      lower="-1.571"
      upper="1.571"
      effort="100"
      velocity="500" />
  </joint>
  <link
    name="sec03">
    <inertial>
      <origin
        xyz="2.71050543121376E-19 0 0"
        rpy="0 0 0" />
      <mass
        value="0.0139800873084746" />
      <inertia
        ixx="3.7862736460452E-07"
        ixy="-4.90793830114797E-24"
        ixz="-3.58892988271445E-23"
        iyy="6.99004365423729E-07"
        iyz="2.45396915057398E-24"
        izz="3.7862736460452E-07" />
    </inertial>
    <visual>
      <origin
        xyz="0 0 0"
        rpy="0 0 0" />
      <geometry>
        <mesh
          filename="package://fullurdf2/meshes/sec03.STL" />
      </geometry>
      <material
        name="">
        <color
          rgba="0.537254901960784 0.349019607843137 0.337254901960784 1" />
      </material>
    </visual>
    <collision>
      <origin
        xyz="0 0 0"
        rpy="0 0 0" />
      <geometry>
        <mesh
          filename="package://fullurdf2/meshes/sec03.STL" />
      </geometry>
    </collision>
  </link>
  <joint
    name="joint03"
    type="revolute">
    <origin
      xyz="0 0.01 0"
      rpy="0 0 0" />
    <parent
      link="sec02" />
    <child
      link="sec03" />
    <axis
      xyz="1 0 0" />
	<dynamics damping="0.00001" friction="0.1"/>
    <limit
      lower="-1.571"
      upper="1.571"
      effort="100"
      velocity="500" />
  </joint>
  <link
    name="sec04">
    <inertial>
      <origin
        xyz="-3.25260651745651E-19 0 0"
        rpy="0 0 0" />
      <mass
        value="0.0139800873084746" />
      <inertia
        ixx="3.7862736460452E-07"
        ixy="4.90793830114798E-24"
        ixz="-4.90793830114797E-23"
        iyy="6.99004365423729E-07"
        iyz="-1.0278932676585E-38"
        izz="3.7862736460452E-07" />
    </inertial>
    <visual>
      <origin
        xyz="0 0 0"
        rpy="0 0 0" />
      <geometry>
        <mesh
          filename="package://fullurdf2/meshes/sec04.STL" />
      </geometry>
      <material
        name="">
        <color
          rgba="0.537254901960784 0.349019607843137 0.337254901960784 1" />
      </material>
    </visual>
    <collision>
      <origin
        xyz="0 0 0"
        rpy="0 0 0" />
      <geometry>
        <mesh
          filename="package://fullurdf2/meshes/sec04.STL" />
      </geometry>
    </collision>
  </link>
  <joint
    name="joint04"
    type="revolute">
    <origin
      xyz="0 0.01 0"
      rpy="0 0 0" />
    <parent
      link="sec03" />
    <child
      link="sec04" />
    <axis
      xyz="1 0 0" />
	<dynamics damping="0.00001" friction="0.1"/>
    <limit
      lower="-1.571"
      upper="1.571"
      effort="100"
      velocity="500" />
  </joint>
  <link
    name="sec05">
    <inertial>
      <origin
        xyz="-2.16840434497101E-19 0 0"
        rpy="0 0 0" />
      <mass
        value="0.0139800873084746" />
      <inertia
        ixx="3.7862736460452E-07"
        ixy="-2.45396915057397E-24"
        ixz="-1.71777840540178E-23"
        iyy="6.99004365423729E-07"
        iyz="-4.20247128011324E-40"
        izz="3.7862736460452E-07" />
    </inertial>
    <visual>
      <origin
        xyz="0 0 0"
        rpy="0 0 0" />
      <geometry>
        <mesh
          filename="package://fullurdf2/meshes/sec05.STL" />
      </geometry>
      <material
        name="">
        <color
          rgba="0.537254901960784 0.349019607843137 0.337254901960784 1" />
      </material>
    </visual>
    <collision>
      <origin
        xyz="0 0 0"
        rpy="0 0 0" />
      <geometry>
        <mesh
          filename="package://fullurdf2/meshes/sec05.STL" />
      </geometry>
    </collision>
  </link>
  <joint
    name="joint05"
    type="revolute">
    <origin
      xyz="0 0.01 0"
      rpy="0 0 0" />
    <parent
      link="sec04" />
    <child
      link="sec05" />
    <axis
      xyz="1 0 0" />
	<dynamics damping="0.00001" friction="0.1"/>
    <limit
      lower="-1.571"
      upper="1.571"
      effort="100"
      velocity="500" />
  </joint>
  <link
    name="sec06">
    <inertial>
      <origin
        xyz="-1.95156391047391E-18 0 -3.46944695195361E-18"
        rpy="0 0 0" />
      <mass
        value="0.0139800873084746" />
      <inertia
        ixx="3.7862736460452E-07"
        ixy="1.22698457528699E-24"
        ixz="-5.67480366070232E-24"
        iyy="6.99004365423729E-07"
        iyz="3.00761747842062E-38"
        izz="3.7862736460452E-07" />
    </inertial>
    <visual>
      <origin
        xyz="0 0 0"
        rpy="0 0 0" />
      <geometry>
        <mesh
          filename="package://fullurdf2/meshes/sec06.STL" />
      </geometry>
      <material
        name="">
        <color
          rgba="0.537254901960784 0.349019607843137 0.337254901960784 1" />
      </material>
    </visual>
    <collision>
      <origin
        xyz="0 0 0"
        rpy="0 0 0" />
      <geometry>
        <mesh
          filename="package://fullurdf2/meshes/sec06.STL" />
      </geometry>
    </collision>
  </link>
  <joint
    name="joint06"
    type="revolute">
    <origin
      xyz="0 0.01 0"
      rpy="0 0 0" />
    <parent
      link="sec05" />
    <child
      link="sec06" />
    <axis
      xyz="1 0 0" />
	<dynamics damping="0.00001" friction="0.1"/>
    <limit
      lower="-1.571"
      upper="1.571"
      effort="100"
      velocity="500" />
  </joint>
  <link
    name="sec07">
    <inertial>
      <origin
        xyz="-1.84314369322536E-18 0 -1.73472347597681E-18"
        rpy="0 0 0" />
      <mass
        value="0.0139800873084746" />
      <inertia
        ixx="3.7862736460452E-07"
        ixy="-1.67610990985475E-38"
        ixz="2.09237994446367E-37"
        iyy="6.99004365423729E-07"
        iyz="1.68127027333929E-38"
        izz="3.7862736460452E-07" />
    </inertial>
    <visual>
      <origin
        xyz="0 0 0"
        rpy="0 0 0" />
      <geometry>
        <mesh
          filename="package://fullurdf2/meshes/sec07.STL" />
      </geometry>
      <material
        name="">
        <color
          rgba="0.537254901960784 0.349019607843137 0.337254901960784 1" />
      </material>
    </visual>
    <collision>
      <origin
        xyz="0 0 0"
        rpy="0 0 0" />
      <geometry>
        <mesh
          filename="package://fullurdf2/meshes/sec07.STL" />
      </geometry>
    </collision>
  </link>
  <joint
    name="joint07"
    type="revolute">
    <origin
      xyz="0 0.01 0"
      rpy="0 0 0" />
    <parent
      link="sec06" />
    <child
      link="sec07" />
    <axis
      xyz="1 0 0" />
	<dynamics damping="0.00001" friction="0.1"/>
    <limit
      lower="-1.571"
      upper="1.571"
      effort="100"
      velocity="500" />
  </joint>
  <link
    name="sec08">
    <inertial>
      <origin
        xyz="-1.62630325872826E-18 0 -1.73472347597681E-18"
        rpy="0 0 0" />
      <mass
        value="0.0139800873084746" />
      <inertia
        ixx="3.7862736460452E-07"
        ixy="-2.45396915057397E-24"
        ixz="-8.82039613106783E-40"
        iyy="6.99004365423729E-07"
        iyz="1.46923067573066E-39"
        izz="3.7862736460452E-07" />
    </inertial>
    <visual>
      <origin
        xyz="0 0 0"
        rpy="0 0 0" />
      <geometry>
        <mesh
          filename="package://fullurdf2/meshes/sec08.STL" />
      </geometry>
      <material
        name="">
        <color
          rgba="0.537254901960784 0.349019607843137 0.337254901960784 1" />
      </material>
    </visual>
    <collision>
      <origin
        xyz="0 0 0"
        rpy="0 0 0" />
      <geometry>
        <mesh
          filename="package://fullurdf2/meshes/sec08.STL" />
      </geometry>
    </collision>
  </link>
  <joint
    name="joint08"
    type="revolute">
    <origin
      xyz="0 0.01 0"
      rpy="0 0 0" />
    <parent
      link="sec07" />
    <child
      link="sec08" />
    <axis
      xyz="1 0 0" />
	<dynamics damping="0.00001" friction="0.1"/>
    <limit
      lower="-1.571"
      upper="1.571"
      effort="100"
      velocity="500" />
  </joint>
  <link
    name="sec09">
    <inertial>
      <origin
        xyz="-1.68051336735253E-18 0 0"
        rpy="0 0 0" />
      <mass
        value="0.0139800873084746" />
      <inertia
        ixx="3.7862736460452E-07"
        ixy="5.11563180875594E-40"
        ixz="3.92635064091837E-23"
        iyy="6.9900436542373E-07"
        iyz="-2.95351140186029E-40"
        izz="3.7862736460452E-07" />
    </inertial>
    <visual>
      <origin
        xyz="0 0 0"
        rpy="0 0 0" />
      <geometry>
        <mesh
          filename="package://fullurdf2/meshes/sec09.STL" />
      </geometry>
      <material
        name="">
        <color
          rgba="0.537254901960784 0.349019607843137 0.337254901960784 1" />
      </material>
    </visual>
    <collision>
      <origin
        xyz="0 0 0"
        rpy="0 0 0" />
      <geometry>
        <mesh
          filename="package://fullurdf2/meshes/sec09.STL" />
      </geometry>
    </collision>
  </link>
  <joint
    name="joint09"
    type="revolute">
    <origin
      xyz="0 0.01 0"
      rpy="0 0 0" />
    <parent
      link="sec08" />
    <child
      link="sec09" />
    <axis
      xyz="1 0 0" />
	<dynamics damping="0.00001" friction="0.1"/>
    <limit
      lower="-1.571"
      upper="1.571"
      effort="100"
      velocity="500" />
  </joint>
  <link
    name="sec10">
    <inertial>
      <origin
        xyz="-3.41523684332934E-18 0 0"
        rpy="0 0 0" />
      <mass
        value="0.0139800873084746" />
      <inertia
        ixx="3.7862736460452E-07"
        ixy="9.81587660229594E-24"
        ixz="6.13492287643496E-23"
        iyy="6.9900436542373E-07"
        iyz="4.90793830114797E-24"
        izz="3.7862736460452E-07" />
    </inertial>
    <visual>
      <origin
        xyz="0 0 0"
        rpy="0 0 0" />
      <geometry>
        <mesh
          filename="package://fullurdf2/meshes/sec10.STL" />
      </geometry>
      <material
        name="">
        <color
          rgba="0.537254901960784 0.349019607843137 0.337254901960784 1" />
      </material>
    </visual>
    <collision>
      <origin
        xyz="0 0 0"
        rpy="0 0 0" />
      <geometry>
        <mesh
          filename="package://fullurdf2/meshes/sec10.STL" />
      </geometry>
    </collision>
  </link>
  <joint
    name="joint10"
    type="revolute">
    <origin
      xyz="0 0.01 0"
      rpy="0 0 0" />
    <parent
      link="sec09" />
    <child
      link="sec10" />
    <axis
      xyz="1 0 0" />
	<dynamics damping="0.00001" friction="0.1"/>
    <limit
      lower="-1.571"
      upper="1.571"
      effort="100"
      velocity="500" />
  </joint>
  <link
    name="base02">
    <inertial>
      <origin
        xyz="-4.55364912443912E-18 0.01 0"
        rpy="0 0 0" />
      <mass
        value="0.0002" />
      <inertia
        ixx="3.33333333333334E-09"
        ixy="1.13745407508819E-26"
        ixz="-5.93103932846684E-26"
        iyy="1.73333333333334E-09"
        iyz="4.82446101602762E-25"
        izz="1.73333333333334E-09" />
    </inertial>
    <visual>
      <origin
        xyz="0 0 0"
        rpy="0 0 0" />
      <geometry>
        <mesh
          filename="package://fullurdf2/meshes/base02.STL" />
      </geometry>
      <material
        name="">
        <color
          rgba="0.792156862745098 0.819607843137255 0.933333333333333 1" />
      </material>
    </visual>
    <collision>
      <origin
        xyz="0 0 0"
        rpy="0 0 0" />
      <geometry>
        <mesh
          filename="package://fullurdf2/meshes/base02.STL" />
      </geometry>
    </collision>
  </link>
  <joint
    name="basejoint02"
    type="fixed">
    <origin
      xyz="0 0 0"
      rpy="0 0 0" />
    <parent
      link="sec10" />
    <child
      link="base02" />
    <axis
      xyz="0 0 0" />
  </joint>
  <link
    name="sec31">
    <inertial>
      <origin
        xyz="0.0025 -1.38777878078145E-17 0"
        rpy="0 0 0" />
      <mass
        value="0.0139800873084746" />
      <inertia
        ixx="6.99004365423729E-07"
        ixy="-1.43749224972972E-23"
        ixz="1.20526705403392E-22"
        iyy="3.7862736460452E-07"
        iyz="-3.92635064091837E-23"
        izz="3.7862736460452E-07" />
    </inertial>
    <visual>
      <origin
        xyz="0 0 0"
        rpy="0 0 0" />
      <geometry>
        <mesh
          filename="package://fullurdf2/meshes/sec31.STL" />
      </geometry>
      <material
        name="">
        <color
          rgba="0.537254901960784 0.349019607843137 0.337254901960784 1" />
      </material>
    </visual>
    <collision>
      <origin
        xyz="0 0 0"
        rpy="0 0 0" />
      <geometry>
        <mesh
          filename="package://fullurdf2/meshes/sec31.STL" />
      </geometry>
    </collision>
  </link>
  <joint
    name="joint31"
    type="fixed">
    <origin
      xyz="0.011 0.01 0"
      rpy="-1.571 0 0" />
    <parent
      link="base02" />
    <child
      link="sec31" />
    <axis
      xyz="1 0 0" />
	<dynamics damping="0.00001" friction="0.1"/>
    <limit
      lower="-1.571"
      upper="1.571"
      effort="100"
      velocity="500" />
  </joint>
  <link
    name="sec32">
    <inertial>
      <origin
        xyz="0.0025 0 0"
        rpy="0 0 0" />
      <mass
        value="0.0139800873084746" />
      <inertia
        ixx="6.9900436542373E-07"
        ixy="-1.43749224972972E-23"
        ixz="1.20526705403392E-22"
        iyy="3.7862736460452E-07"
        iyz="-5.07664868024993E-23"
        izz="3.7862736460452E-07" />
    </inertial>
    <visual>
      <origin
        xyz="0 0 0"
        rpy="0 0 0" />
      <geometry>
        <mesh
          filename="package://fullurdf2/meshes/sec32.STL" />
      </geometry>
      <material
        name="">
        <color
          rgba="0.537254901960784 0.349019607843137 0.337254901960784 1" />
      </material>
    </visual>
    <collision>
      <origin
        xyz="0 0 0"
        rpy="0 0 0" />
      <geometry>
        <mesh
          filename="package://fullurdf2/meshes/sec32.STL" />
      </geometry>
    </collision>
  </link>
  <joint
    name="joint32"
    type="revolute">
    <origin
      xyz="0.01 0 0"
      rpy="0 0 0" />
    <parent
      link="sec31" />
    <child
      link="sec32" />
    <axis
      xyz="0 0 1" />
	<dynamics damping="0.00001" friction="0.1"/>
    <limit
      lower="-1.571"
      upper="1.571"
      effort="100"
      velocity="500" />
  </joint>
  <link
    name="sec33">
    <inertial>
      <origin
        xyz="0.0025 0 -5.20417042793042E-18"
        rpy="0 0 0" />
      <mass
        value="0.0139800873084746" />
      <inertia
        ixx="6.99004365423729E-07"
        ixy="-9.46698419614924E-24"
        ixz="1.22980674553966E-22"
        iyy="3.7862736460452E-07"
        iyz="-5.07664868024992E-23"
        izz="3.7862736460452E-07" />
    </inertial>
    <visual>
      <origin
        xyz="0 0 0"
        rpy="0 0 0" />
      <geometry>
        <mesh
          filename="package://fullurdf2/meshes/sec33.STL" />
      </geometry>
      <material
        name="">
        <color
          rgba="0.537254901960784 0.349019607843137 0.337254901960784 1" />
      </material>
    </visual>
    <collision>
      <origin
        xyz="0 0 0"
        rpy="0 0 0" />
      <geometry>
        <mesh
          filename="package://fullurdf2/meshes/sec33.STL" />
      </geometry>
    </collision>
  </link>
  <joint
    name="joint33"
    type="revolute">
    <origin
      xyz="0.01 0 0"
      rpy="0 0 0" />
    <parent
      link="sec32" />
    <child
      link="sec33" />
    <axis
      xyz="0 0 1" />
	<dynamics damping="0.00001" friction="0.1"/>
    <limit
      lower="-1.571"
      upper="1.571"
      effort="100"
      velocity="500" />
  </joint>
  <link
    name="sec34">
    <inertial>
      <origin
        xyz="0.00249999999999999 0 -6.93889390390723E-18"
        rpy="0 0 0" />
      <mass
        value="0.0139800873084746" />
      <inertia
        ixx="6.99004365423729E-07"
        ixy="-9.46698419614924E-24"
        ixz="1.22980674553966E-22"
        iyy="3.7862736460452E-07"
        iyz="-5.07664868024993E-23"
        izz="3.7862736460452E-07" />
    </inertial>
    <visual>
      <origin
        xyz="0 0 0"
        rpy="0 0 0" />
      <geometry>
        <mesh
          filename="package://fullurdf2/meshes/sec34.STL" />
      </geometry>
      <material
        name="">
        <color
          rgba="0.537254901960784 0.349019607843137 0.337254901960784 1" />
      </material>
    </visual>
    <collision>
      <origin
        xyz="0 0 0"
        rpy="0 0 0" />
      <geometry>
        <mesh
          filename="package://fullurdf2/meshes/sec34.STL" />
      </geometry>
    </collision>
  </link>
  <joint
    name="joint34"
    type="revolute">
    <origin
      xyz="0.01 0 0"
      rpy="0 0 0" />
    <parent
      link="sec33" />
    <child
      link="sec34" />
    <axis
      xyz="0 0 1" />
	<dynamics damping="0.00001" friction="0.1"/>
    <limit
      lower="-1.571"
      upper="1.571"
      effort="100"
      velocity="500" />
  </joint>
  <link
    name="sec35">
    <inertial>
      <origin
        xyz="0.0025 0 -5.20417042793042E-18"
        rpy="0 0 0" />
      <mass
        value="0.0139800873084746" />
      <inertia
        ixx="6.99004365423729E-07"
        ixy="-1.43749224972973E-23"
        ixz="1.2543464370454E-22"
        iyy="3.7862736460452E-07"
        iyz="-5.07664868024992E-23"
        izz="3.7862736460452E-07" />
    </inertial>
    <visual>
      <origin
        xyz="0 0 0"
        rpy="0 0 0" />
      <geometry>
        <mesh
          filename="package://fullurdf2/meshes/sec35.STL" />
      </geometry>
      <material
        name="">
        <color
          rgba="0.537254901960784 0.349019607843137 0.337254901960784 1" />
      </material>
    </visual>
    <collision>
      <origin
        xyz="0 0 0"
        rpy="0 0 0" />
      <geometry>
        <mesh
          filename="package://fullurdf2/meshes/sec35.STL" />
      </geometry>
    </collision>
  </link>
  <joint
    name="joint35"
    type="revolute">
    <origin
      xyz="0.01 0 0"
      rpy="0 0 0" />
    <parent
      link="sec34" />
    <child
      link="sec35" />
    <axis
      xyz="0 0 1" />
	<dynamics damping="0.00001" friction="0.1"/>
    <limit
      lower="-1.571"
      upper="1.571"
      effort="100"
      velocity="500" />
  </joint>
  <link
    name="sec36">
    <inertial>
      <origin
        xyz="0.0025 1.38777878078145E-17 -5.20417042793042E-18"
        rpy="0 0 0" />
      <mass
        value="0.0139800873084746" />
      <inertia
        ixx="6.9900436542373E-07"
        ixy="-1.43749224972972E-23"
        ixz="1.22980674553966E-22"
        iyy="3.7862736460452E-07"
        iyz="-5.07664868024992E-23"
        izz="3.7862736460452E-07" />
    </inertial>
    <visual>
      <origin
        xyz="0 0 0"
        rpy="0 0 0" />
      <geometry>
        <mesh
          filename="package://fullurdf2/meshes/sec36.STL" />
      </geometry>
      <material
        name="">
        <color
          rgba="0.537254901960784 0.349019607843137 0.337254901960784 1" />
      </material>
    </visual>
    <collision>
      <origin
        xyz="0 0 0"
        rpy="0 0 0" />
      <geometry>
        <mesh
          filename="package://fullurdf2/meshes/sec36.STL" />
      </geometry>
    </collision>
  </link>
  <joint
    name="joint36"
    type="revolute">
    <origin
      xyz="0.01 0 0"
      rpy="0 0 0" />
    <parent
      link="sec35" />
    <child
      link="sec36" />
    <axis
      xyz="0 0 1" />
	<dynamics damping="0.00001" friction="0.1"/>
    <limit
      lower="-1.571"
      upper="1.571"
      effort="100"
      velocity="500" />
  </joint>
  <link
    name="sec37">
    <inertial>
      <origin
        xyz="0.0025 1.38777878078145E-17 -5.20417042793042E-18"
        rpy="0 0 0" />
      <mass
        value="0.0139800873084746" />
      <inertia
        ixx="6.9900436542373E-07"
        ixy="-1.43749224972972E-23"
        ixz="1.22980674553966E-22"
        iyy="3.7862736460452E-07"
        iyz="-5.07664868024992E-23"
        izz="3.7862736460452E-07" />
    </inertial>
    <visual>
      <origin
        xyz="0 0 0"
        rpy="0 0 0" />
      <geometry>
        <mesh
          filename="package://fullurdf2/meshes/sec37.STL" />
      </geometry>
      <material
        name="">
        <color
          rgba="0.537254901960784 0.349019607843137 0.337254901960784 1" />
      </material>
    </visual>
    <collision>
      <origin
        xyz="0 0 0"
        rpy="0 0 0" />
      <geometry>
        <mesh
          filename="package://fullurdf2/meshes/sec37.STL" />
      </geometry>
    </collision>
  </link>
  <joint
    name="joint37"
    type="revolute">
    <origin
      xyz="0.01 0 0"
      rpy="0 0 0" />
    <parent
      link="sec36" />
    <child
      link="sec37" />
    <axis
      xyz="0 0 1" />
	<dynamics damping="0.00001" friction="0.1"/>
    <limit
      lower="-1.571"
      upper="1.571"
      effort="100"
      velocity="500" />
  </joint>
  <link
    name="sec38">
    <inertial>
      <origin
        xyz="0.0025 1.38777878078145E-17 -5.20417042793042E-18"
        rpy="0 0 0" />
      <mass
        value="0.0139800873084746" />
      <inertia
        ixx="6.9900436542373E-07"
        ixy="-1.43749224972972E-23"
        ixz="1.2543464370454E-22"
        iyy="3.7862736460452E-07"
        iyz="-5.07664868024993E-23"
        izz="3.7862736460452E-07" />
    </inertial>
    <visual>
      <origin
        xyz="0 0 0"
        rpy="0 0 0" />
      <geometry>
        <mesh
          filename="package://fullurdf2/meshes/sec38.STL" />
      </geometry>
      <material
        name="">
        <color
          rgba="0.537254901960784 0.349019607843137 0.337254901960784 1" />
      </material>
    </visual>
    <collision>
      <origin
        xyz="0 0 0"
        rpy="0 0 0" />
      <geometry>
        <mesh
          filename="package://fullurdf2/meshes/sec38.STL" />
      </geometry>
    </collision>
  </link>
  <joint
    name="joint38"
    type="revolute">
    <origin
      xyz="0.01 0 0"
      rpy="0 0 0" />
    <parent
      link="sec37" />
    <child
      link="sec38" />
    <axis
      xyz="0 0 1" />
	<dynamics damping="0.00001" friction="0.1"/>
    <limit
      lower="-1.571"
      upper="1.571"
      effort="100"
      velocity="500" />
  </joint>
  <link
    name="sec39">
    <inertial>
      <origin
        xyz="0.0025 1.3878E-17 -6.9389E-18"
        rpy="0 0 0" />
      <mass
        value="0.01398" />
      <inertia
        ixx="6.99E-07"
        ixy="-1.4375E-23"
        ixz="1.2298E-22"
        iyy="3.7863E-07"
        iyz="-5.0766E-23"
        izz="3.7863E-07" />
    </inertial>
    <visual>
      <origin
        xyz="0 0 0"
        rpy="0 0 0" />
      <geometry>
        <mesh
          filename="package://fullurdf2/meshes/sec39.STL" />
      </geometry>
      <material
        name="">
        <color
          rgba="0.53725 0.34902 0.33725 1" />
      </material>
    </visual>
    <collision>
      <origin
        xyz="0 0 0"
        rpy="0 0 0" />
      <geometry>
        <mesh
          filename="package://fullurdf2/meshes/sec39.STL" />
      </geometry>
    </collision>
  </link>
  <joint
    name="joint39"
    type="revolute">
    <origin
      xyz="0.01 0 0"
      rpy="0 0 0" />
    <parent
      link="sec38" />
    <child
      link="sec39" />
    <axis
      xyz="0 0 1" />
	<dynamics damping="0.00001" friction="0.1"/>
    <limit
      lower="-1.571"
      upper="1.571"
      effort="100"
      velocity="500" />
  </joint>
  <link
    name="sec40">
    <inertial>
      <origin
        xyz="0.0098619 -1.3878E-17 -3.4694E-18"
        rpy="0 0 0" />
      <mass
        value="0.057326" />
      <inertia
        ixx="2.9166E-06"
        ixy="6.5493E-24"
        ixz="3.6283E-22"
        iyy="2.2417E-06"
        iyz="1.6868E-23"
        izz="2.2417E-06" />
    </inertial>
    <visual>
      <origin
        xyz="0 0 0"
        rpy="0 0 0" />
      <geometry>
        <mesh
          filename="package://fullurdf2/meshes/sec40.STL" />
      </geometry>
      <material
        name="">
        <color
          rgba="0.53725 0.34902 0.33725 1" />
      </material>
    </visual>
    <collision>
      <origin
        xyz="0 0 0"
        rpy="0 0 0" />
      <geometry>
        <mesh
          filename="package://fullurdf2/meshes/sec40.STL" />
      </geometry>
    </collision>
  </link>
  <joint
    name="joint40"
    type="revolute">
    <origin
      xyz="0.01 0 0"
      rpy="0 0 0" />
    <parent
      link="sec39" />
    <child
      link="sec40" />
    <axis
      xyz="0 0 1" />
	<dynamics damping="0.00001" friction="0.1"/>
    <limit
      lower="-1.571"
      upper="1.571"
      effort="100"
      velocity="500" />
  </joint>
  <link
    name="sec41">
    <inertial>
      <origin
        xyz="-0.0025 -1.38777878078145E-17 -1.73472347597681E-18"
        rpy="0 0 0" />
      <mass
        value="0.0139800873084746" />
      <inertia
        ixx="6.99004365423729E-07"
        ixy="3.53648198512507E-25"
        ixz="-3.48660332929381E-23"
        iyy="3.7862736460452E-07"
        iyz="1.62575456225526E-23"
        izz="3.7862736460452E-07" />
    </inertial>
    <visual>
      <origin
        xyz="0 0 0"
        rpy="0 0 0" />
      <geometry>
        <mesh
          filename="package://fullurdf2/meshes/sec41.STL" />
      </geometry>
      <material
        name="">
        <color
          rgba="0.537254901960784 0.349019607843137 0.337254901960784 1" />
      </material>
    </visual>
    <collision>
      <origin
        xyz="0 0 0"
        rpy="0 0 0" />
      <geometry>
        <mesh
          filename="package://fullurdf2/meshes/sec41.STL" />
      </geometry>
    </collision>
  </link>
  <joint
    name="joint41"
    type="fixed">
    <origin
      xyz="-0.011 0.01 0"
      rpy="1.571 0 0" />
    <parent
      link="base02" />
    <child
      link="sec41" />
    <axis
      xyz="1 0 1" />
	<dynamics damping="0.00001" friction="0.1"/>
    <limit
      lower="-1.571"
      upper="1.571"
      effort="100"
      velocity="500" />
  </joint>
  <link
    name="sec42">
    <inertial>
      <origin
        xyz="-0.0025 0 -5.20417042793042E-18"
        rpy="0 0 0" />
      <mass
        value="0.0139800873084746" />
      <inertia
        ixx="6.99004365423729E-07"
        ixy="3.53648198512512E-25"
        ixz="-3.48660332929381E-23"
        iyy="3.7862736460452E-07"
        iyz="-3.7729775690075E-23"
        izz="3.7862736460452E-07" />
    </inertial>
    <visual>
      <origin
        xyz="0 0 0"
        rpy="0 0 0" />
      <geometry>
        <mesh
          filename="package://fullurdf2/meshes/sec42.STL" />
      </geometry>
      <material
        name="">
        <color
          rgba="0.537254901960784 0.349019607843137 0.337254901960784 1" />
      </material>
    </visual>
    <collision>
      <origin
        xyz="0 0 0"
        rpy="0 0 0" />
      <geometry>
        <mesh
          filename="package://fullurdf2/meshes/sec42.STL" />
      </geometry>
    </collision>
  </link>
  <joint
    name="joint42"
    type="revolute">
    <origin
      xyz="-0.01 0 0"
      rpy="0 0 0" />
    <parent
      link="sec41" />
    <child
      link="sec42" />
    <axis
      xyz="0 0 1" />
	<dynamics damping="0.00001" friction="0.1"/>
    <limit
      lower="-1.571"
      upper="1.571"
      effort="100"
      velocity="500" />
  </joint>
  <link
    name="sec43">
    <inertial>
      <origin
        xyz="-0.0025 0 -6.93889390390723E-18"
        rpy="0 0 0" />
      <mass
        value="0.0139800873084746" />
      <inertia
        ixx="6.99004365423729E-07"
        ixy="5.26158649966047E-24"
        ixz="-4.4681909895234E-23"
        iyy="3.7862736460452E-07"
        iyz="-1.07361150337611E-23"
        izz="3.7862736460452E-07" />
    </inertial>
    <visual>
      <origin
        xyz="0 0 0"
        rpy="0 0 0" />
      <geometry>
        <mesh
          filename="package://fullurdf2/meshes/sec43.STL" />
      </geometry>
      <material
        name="">
        <color
          rgba="0.537254901960784 0.349019607843137 0.337254901960784 1" />
      </material>
    </visual>
    <collision>
      <origin
        xyz="0 0 0"
        rpy="0 0 0" />
      <geometry>
        <mesh
          filename="package://fullurdf2/meshes/sec43.STL" />
      </geometry>
    </collision>
  </link>
  <joint
    name="joint43"
    type="revolute">
    <origin
      xyz="-0.01 0 0"
      rpy="0 0 0" />
    <parent
      link="sec42" />
    <child
      link="sec43" />
    <axis
      xyz="0 0 1" />
	<dynamics damping="0.00001" friction="0.1"/>
    <limit
      lower="-1.571"
      upper="1.571"
      effort="100"
      velocity="500" />
  </joint>
  <link
    name="sec44">
    <inertial>
      <origin
        xyz="-0.0025 0 -5.20417042793042E-18"
        rpy="0 0 0" />
      <mass
        value="0.0139800873084746" />
      <inertia
        ixx="6.99004365423729E-07"
        ixy="2.80761734908649E-24"
        ixz="-3.9773971594086E-23"
        iyy="3.7862736460452E-07"
        iyz="1.62575456225526E-23"
        izz="3.7862736460452E-07" />
    </inertial>
    <visual>
      <origin
        xyz="0 0 0"
        rpy="0 0 0" />
      <geometry>
        <mesh
          filename="package://fullurdf2/meshes/sec44.STL" />
      </geometry>
      <material
        name="">
        <color
          rgba="0.537254901960784 0.349019607843137 0.337254901960784 1" />
      </material>
    </visual>
    <collision>
      <origin
        xyz="0 0 0"
        rpy="0 0 0" />
      <geometry>
        <mesh
          filename="package://fullurdf2/meshes/sec44.STL" />
      </geometry>
    </collision>
  </link>
  <joint
    name="joint44"
    type="revolute">
    <origin
      xyz="-0.01 0 0"
      rpy="0 0 0" />
    <parent
      link="sec43" />
    <child
      link="sec44" />
    <axis
      xyz="0 0 1" />
	<dynamics damping="0.00001" friction="0.1"/>
    <limit
      lower="-1.571"
      upper="1.571"
      effort="100"
      velocity="500" />
  </joint>
  <link
    name="sec45">
    <inertial>
      <origin
        xyz="-0.0025 0 -5.20417042793042E-18"
        rpy="0 0 0" />
      <mass
        value="0.0139800873084746" />
      <inertia
        ixx="6.99004365423729E-07"
        ixy="2.80761734908649E-24"
        ixz="-3.9773971594086E-23"
        iyy="3.7862736460452E-07"
        iyz="-3.7729775690075E-23"
        izz="3.7862736460452E-07" />
    </inertial>
    <visual>
      <origin
        xyz="0 0 0"
        rpy="0 0 0" />
      <geometry>
        <mesh
          filename="package://fullurdf2/meshes/sec45.STL" />
      </geometry>
      <material
        name="">
        <color
          rgba="0.537254901960784 0.349019607843137 0.337254901960784 1" />
      </material>
    </visual>
    <collision>
      <origin
        xyz="0 0 0"
        rpy="0 0 0" />
      <geometry>
        <mesh
          filename="package://fullurdf2/meshes/sec45.STL" />
      </geometry>
    </collision>
  </link>
  <joint
    name="joint45"
    type="revolute">
    <origin
      xyz="-0.01 0 0"
      rpy="0 0 0" />
    <parent
      link="sec44" />
    <child
      link="sec45" />
    <axis
      xyz="0 0 1" />
	<dynamics damping="0.00001" friction="0.1"/>
    <limit
      lower="-1.571"
      upper="1.571"
      effort="100"
      velocity="500" />
  </joint>
  <link
    name="sec46">
    <inertial>
      <origin
        xyz="-0.0025 0 -6.93889390390723E-18"
        rpy="0 0 0" />
      <mass
        value="0.0139800873084746" />
      <inertia
        ixx="6.99004365423729E-07"
        ixy="2.8076173490865E-24"
        ixz="-4.4681909895234E-23"
        iyy="3.7862736460452E-07"
        iyz="-1.07361150337612E-23"
        izz="3.7862736460452E-07" />
    </inertial>
    <visual>
      <origin
        xyz="0 0 0"
        rpy="0 0 0" />
      <geometry>
        <mesh
          filename="package://fullurdf2/meshes/sec46.STL" />
      </geometry>
      <material
        name="">
        <color
          rgba="0.537254901960784 0.349019607843137 0.337254901960784 1" />
      </material>
    </visual>
    <collision>
      <origin
        xyz="0 0 0"
        rpy="0 0 0" />
      <geometry>
        <mesh
          filename="package://fullurdf2/meshes/sec46.STL" />
      </geometry>
    </collision>
  </link>
  <joint
    name="joint46"
    type="revolute">
    <origin
      xyz="-0.01 0 0"
      rpy="0 0 0" />
    <parent
      link="sec45" />
    <child
      link="sec46" />
    <axis
      xyz="0 0 1" />
	<dynamics damping="0.00001" friction="0.1"/>
    <limit
      lower="-1.571"
      upper="1.571"
      effort="100"
      velocity="500" />
  </joint>
  <link
    name="sec47">
    <inertial>
      <origin
        xyz="-0.0025 0 -5.20417042793042E-18"
        rpy="0 0 0" />
      <mass
        value="0.0139800873084746" />
      <inertia
        ixx="6.9900436542373E-07"
        ixy="2.8076173490865E-24"
        ixz="-3.48660332929381E-23"
        iyy="3.7862736460452E-07"
        iyz="4.75456522923716E-24"
        izz="3.7862736460452E-07" />
    </inertial>
    <visual>
      <origin
        xyz="0 0 0"
        rpy="0 0 0" />
      <geometry>
        <mesh
          filename="package://fullurdf2/meshes/sec47.STL" />
      </geometry>
      <material
        name="">
        <color
          rgba="0.537254901960784 0.349019607843137 0.337254901960784 1" />
      </material>
    </visual>
    <collision>
      <origin
        xyz="0 0 0"
        rpy="0 0 0" />
      <geometry>
        <mesh
          filename="package://fullurdf2/meshes/sec47.STL" />
      </geometry>
    </collision>
  </link>
  <joint
    name="joint47"
    type="revolute">
    <origin
      xyz="-0.01 0 0"
      rpy="0 0 0" />
    <parent
      link="sec46" />
    <child
      link="sec47" />
    <axis
      xyz="0 0 1" />
	<dynamics damping="0.00001" friction="0.1"/>
    <limit
      lower="-1.571"
      upper="1.571"
      effort="100"
      velocity="500" />
  </joint>
  <link
    name="sec48">
    <inertial>
      <origin
        xyz="-0.0025 1.38777878078145E-17 -5.20417042793042E-18"
        rpy="0 0 0" />
      <mass
        value="0.0139800873084746" />
      <inertia
        ixx="6.9900436542373E-07"
        ixy="3.53648198512522E-25"
        ixz="-3.48660332929381E-23"
        iyy="3.7862736460452E-07"
        iyz="-4.92327560833906E-23"
        izz="3.7862736460452E-07" />
    </inertial>
    <visual>
      <origin
        xyz="0 0 0"
        rpy="0 0 0" />
      <geometry>
        <mesh
          filename="package://fullurdf2/meshes/sec48.STL" />
      </geometry>
      <material
        name="">
        <color
          rgba="0.537254901960784 0.349019607843137 0.337254901960784 1" />
      </material>
    </visual>
    <collision>
      <origin
        xyz="0 0 0"
        rpy="0 0 0" />
      <geometry>
        <mesh
          filename="package://fullurdf2/meshes/sec48.STL" />
      </geometry>
    </collision>
  </link>
  <joint
    name="joint48"
    type="revolute">
    <origin
      xyz="-0.01 0 0"
      rpy="0 0 0" />
    <parent
      link="sec47" />
    <child
      link="sec48" />
    <axis
      xyz="0 0 1" />
	<dynamics damping="0.00001" friction="0.1"/>
    <limit
      lower="-1.571"
      upper="1.571"
      effort="100"
      velocity="500" />
  </joint>
  <link
    name="sec49">
    <inertial>
      <origin
        xyz="-0.0025 0 -5.20417042793042E-18"
        rpy="0 0 0" />
      <mass
        value="0.0139800873084746" />
      <inertia
        ixx="6.9900436542373E-07"
        ixy="2.80761734908651E-24"
        ixz="-3.97739715940861E-23"
        iyy="3.7862736460452E-07"
        iyz="-2.22390954270767E-23"
        izz="3.7862736460452E-07" />
    </inertial>
    <visual>
      <origin
        xyz="0 0 0"
        rpy="0 0 0" />
      <geometry>
        <mesh
          filename="package://fullurdf2/meshes/sec49.STL" />
      </geometry>
      <material
        name="">
        <color
          rgba="0.537254901960784 0.349019607843137 0.337254901960784 1" />
      </material>
    </visual>
    <collision>
      <origin
        xyz="0 0 0"
        rpy="0 0 0" />
      <geometry>
        <mesh
          filename="package://fullurdf2/meshes/sec49.STL" />
      </geometry>
    </collision>
  </link>
  <joint
    name="joint49"
    type="revolute">
    <origin
      xyz="-0.01 0 0"
      rpy="0 0 0" />
    <parent
      link="sec48" />
    <child
      link="sec49" />
    <axis
      xyz="0 0 1" />
	<dynamics damping="0.00001" friction="0.1"/>
    <limit
      lower="-1.571"
      upper="1.571"
      effort="100"
      velocity="500" />
  </joint>
  <link
    name="sec50">
    <inertial>
      <origin
        xyz="-0.0098619 1.3878E-17 3.4694E-18"
        rpy="0 0 0" />
      <mass
        value="0.057326" />
      <inertia
        ixx="2.9166E-06"
        ixy="-5.3744E-23"
        ixz="1.0238E-22"
        iyy="2.2417E-06"
        iyz="-6.241E-23"
        izz="2.2417E-06" />
    </inertial>
    <visual>
      <origin
        xyz="0 0 0"
        rpy="0 0 0" />
      <geometry>
        <mesh
          filename="package://fullurdf2/meshes/sec50.STL" />
      </geometry>
      <material
        name="">
        <color
          rgba="0.53725 0.34902 0.33725 1" />
      </material>
    </visual>
    <collision>
      <origin
        xyz="0 0 0"
        rpy="0 0 0" />
      <geometry>
        <mesh
          filename="package://fullurdf2/meshes/sec50.STL" />
      </geometry>
    </collision>
  </link>
  <joint
    name="joint50"
    type="revolute">
    <origin
      xyz="-0.01 0 0"
      rpy="0 0 0" />
    <parent
      link="sec49" />
    <child
      link="sec50" />
    <axis
      xyz="0 0 1" />
	<dynamics damping="0.00001" friction="0.1"/>
    <limit
      lower="-1.571"
      upper="1.571"
      effort="100"
      velocity="500" />
  </joint>
  <link
    name="sec11">
    <inertial>
      <origin
        xyz="0.0025 -1.7347E-18 0"
        rpy="0 0 0" />
      <mass
        value="0.01398" />
      <inertia
        ixx="6.99E-07"
        ixy="-1.2747E-39"
        ixz="8.4139E-39"
        iyy="3.7863E-07"
        iyz="2.3773E-23"
        izz="3.7863E-07" />
    </inertial>
    <visual>
      <origin
        xyz="0 0 0"
        rpy="0 0 0" />
      <geometry>
        <mesh
          filename="package://fullurdf2/meshes/sec11.STL" />
      </geometry>
      <material
        name="">
        <color
          rgba="0.53725 0.34902 0.33725 1" />
      </material>
    </visual>
    <collision>
      <origin
        xyz="0 0 0"
        rpy="0 0 0" />
      <geometry>
        <mesh
          filename="package://fullurdf2/meshes/sec11.STL" />
      </geometry>
    </collision>
  </link>
  <joint
    name="joint11"
    type="fixed">
    <origin
      xyz="0.011 -0.005 0"
      rpy="-1.571 0 0" />
    <parent
      link="base_link" />
    <child
      link="sec11" />
    <axis
      xyz="1 0 1" />
	<dynamics damping="0.00001" friction="0.1"/>
    <limit
      lower="-1.571"
      upper="1.571"
      effort="100"
      velocity="500" />
  </joint>
  <link
    name="sec12">
    <inertial>
      <origin
        xyz="0.0025 0 1.73472347597681E-18"
        rpy="0 0 0" />
      <mass
        value="0.0139800873084746" />
      <inertia
        ixx="6.99004365423729E-07"
        ixy="2.45396915057399E-24"
        ixz="9.81587660229592E-24"
        iyy="3.7862736460452E-07"
        iyz="1.22698457528699E-23"
        izz="3.7862736460452E-07" />
    </inertial>
    <visual>
      <origin
        xyz="0 0 0"
        rpy="0 0 0" />
      <geometry>
        <mesh
          filename="package://fullurdf2/meshes/sec12.STL" />
      </geometry>
      <material
        name="">
        <color
          rgba="0.537254901960784 0.349019607843137 0.337254901960784 1" />
      </material>
    </visual>
    <collision>
      <origin
        xyz="0 0 0"
        rpy="0 0 0" />
      <geometry>
        <mesh
          filename="package://fullurdf2/meshes/sec12.STL" />
      </geometry>
    </collision>
  </link>
  <joint
    name="joint12"
    type="revolute">
    <origin
      xyz="0.01 0 0"
      rpy="0 0 0" />
    <parent
      link="sec11" />
    <child
      link="sec12" />
    <axis
      xyz="0 0 1" />
	<dynamics damping="0.00001" friction="0.1"/>
    <limit
      lower="-1.571"
      upper="1.571"
      effort="100"
      velocity="500" />
  </joint>
  <link
    name="sec13">
    <inertial>
      <origin
        xyz="0.0025 0 1.73472347597681E-18"
        rpy="0 0 0" />
      <mass
        value="0.0139800873084746" />
      <inertia
        ixx="6.99004365423729E-07"
        ixy="-2.45396915057399E-24"
        ixz="-9.81587660229591E-24"
        iyy="3.7862736460452E-07"
        iyz="1.22698457528699E-23"
        izz="3.7862736460452E-07" />
    </inertial>
    <visual>
      <origin
        xyz="0 0 0"
        rpy="0 0 0" />
      <geometry>
        <mesh
          filename="package://fullurdf2/meshes/sec13.STL" />
      </geometry>
      <material
        name="">
        <color
          rgba="0.537254901960784 0.349019607843137 0.337254901960784 1" />
      </material>
    </visual>
    <collision>
      <origin
        xyz="0 0 0"
        rpy="0 0 0" />
      <geometry>
        <mesh
          filename="package://fullurdf2/meshes/sec13.STL" />
      </geometry>
    </collision>
  </link>
  <joint
    name="joint13"
    type="revolute">
    <origin
      xyz="0.01 0 0"
      rpy="0 0 0" />
    <parent
      link="sec12" />
    <child
      link="sec13" />
    <axis
      xyz="0 0 1" />
	<dynamics damping="0.00001" friction="0.1"/>
    <limit
      lower="-1.571"
      upper="1.571"
      effort="100"
      velocity="500" />
  </joint>
  <link
    name="sec14">
    <inertial>
      <origin
        xyz="0.0025 0 1.73472347597681E-18"
        rpy="0 0 0" />
      <mass
        value="0.0139800873084746" />
      <inertia
        ixx="6.99004365423729E-07"
        ixy="2.45396915057399E-24"
        ixz="9.81587660229591E-24"
        iyy="3.7862736460452E-07"
        iyz="1.22698457528699E-23"
        izz="3.7862736460452E-07" />
    </inertial>
    <visual>
      <origin
        xyz="0 0 0"
        rpy="0 0 0" />
      <geometry>
        <mesh
          filename="package://fullurdf2/meshes/sec14.STL" />
      </geometry>
      <material
        name="">
        <color
          rgba="0.537254901960784 0.349019607843137 0.337254901960784 1" />
      </material>
    </visual>
    <collision>
      <origin
        xyz="0 0 0"
        rpy="0 0 0" />
      <geometry>
        <mesh
          filename="package://fullurdf2/meshes/sec14.STL" />
      </geometry>
    </collision>
  </link>
  <joint
    name="joint14"
    type="revolute">
    <origin
      xyz="0.01 0 0"
      rpy="0 0 0" />
    <parent
      link="sec13" />
    <child
      link="sec14" />
    <axis
      xyz="0 0 1" />
	<dynamics damping="0.00001" friction="0.1"/>
    <limit
      lower="-1.571"
      upper="1.571"
      effort="100"
      velocity="500" />
  </joint>
  <link
    name="sec15">
    <inertial>
      <origin
        xyz="0.0025 0 1.73472347597681E-18"
        rpy="0 0 0" />
      <mass
        value="0.0139800873084746" />
      <inertia
        ixx="6.99004365423729E-07"
        ixy="-2.45396915057399E-24"
        ixz="-9.81587660229591E-24"
        iyy="3.7862736460452E-07"
        iyz="1.22698457528699E-23"
        izz="3.7862736460452E-07" />
    </inertial>
    <visual>
      <origin
        xyz="0 0 0"
        rpy="0 0 0" />
      <geometry>
        <mesh
          filename="package://fullurdf2/meshes/sec15.STL" />
      </geometry>
      <material
        name="">
        <color
          rgba="0.537254901960784 0.349019607843137 0.337254901960784 1" />
      </material>
    </visual>
    <collision>
      <origin
        xyz="0 0 0"
        rpy="0 0 0" />
      <geometry>
        <mesh
          filename="package://fullurdf2/meshes/sec15.STL" />
      </geometry>
    </collision>
  </link>
  <joint
    name="joint15"
    type="revolute">
    <origin
      xyz="0.01 0 0"
      rpy="0 0 0" />
    <parent
      link="sec14" />
    <child
      link="sec15" />
    <axis
      xyz="0 0 1" />
	<dynamics damping="0.00001" friction="0.1"/>
    <limit
      lower="-1.571"
      upper="1.571"
      effort="100"
      velocity="500" />
  </joint>
  <link
    name="sec16">
    <inertial>
      <origin
        xyz="0.0025 0 1.73472347597681E-18"
        rpy="0 0 0" />
      <mass
        value="0.0139800873084746" />
      <inertia
        ixx="6.99004365423729E-07"
        ixy="2.45396915057399E-24"
        ixz="9.81587660229591E-24"
        iyy="3.7862736460452E-07"
        iyz="1.22698457528699E-23"
        izz="3.7862736460452E-07" />
    </inertial>
    <visual>
      <origin
        xyz="0 0 0"
        rpy="0 0 0" />
      <geometry>
        <mesh
          filename="package://fullurdf2/meshes/sec16.STL" />
      </geometry>
      <material
        name="">
        <color
          rgba="0.537254901960784 0.349019607843137 0.337254901960784 1" />
      </material>
    </visual>
    <collision>
      <origin
        xyz="0 0 0"
        rpy="0 0 0" />
      <geometry>
        <mesh
          filename="package://fullurdf2/meshes/sec16.STL" />
      </geometry>
    </collision>
  </link>
  <joint
    name="joint16"
    type="revolute">
    <origin
      xyz="0.01 0 0"
      rpy="0 0 0" />
    <parent
      link="sec15" />
    <child
      link="sec16" />
    <axis
      xyz="0 0 1" />
	<dynamics damping="0.00001" friction="0.1"/>
    <limit
      lower="-1.571"
      upper="1.571"
      effort="100"
      velocity="500" />
  </joint>
  <link
    name="sec17">
    <inertial>
      <origin
        xyz="0.0025 0 1.73472347597681E-18"
        rpy="0 0 0" />
      <mass
        value="0.0139800873084746" />
      <inertia
        ixx="6.9900436542373E-07"
        ixy="7.98179605279416E-40"
        ixz="2.55417473689413E-39"
        iyy="3.7862736460452E-07"
        iyz="2.37728261461855E-23"
        izz="3.7862736460452E-07" />
    </inertial>
    <visual>
      <origin
        xyz="0 0 0"
        rpy="0 0 0" />
      <geometry>
        <mesh
          filename="package://fullurdf2/meshes/sec17.STL" />
      </geometry>
      <material
        name="">
        <color
          rgba="0.537254901960784 0.349019607843137 0.337254901960784 1" />
      </material>
    </visual>
    <collision>
      <origin
        xyz="0 0 0"
        rpy="0 0 0" />
      <geometry>
        <mesh
          filename="package://fullurdf2/meshes/sec17.STL" />
      </geometry>
    </collision>
  </link>
  <joint
    name="joint17"
    type="revolute">
    <origin
      xyz="0.00999999999999999 0 0"
      rpy="0 0 0" />
    <parent
      link="sec16" />
    <child
      link="sec17" />
    <axis
      xyz="0 0 1" />
	<dynamics damping="0.00001" friction="0.1"/>
    <limit
      lower="-1.571"
      upper="1.571"
      effort="100"
      velocity="500" />
  </joint>
  <link
    name="sec18">
    <inertial>
      <origin
        xyz="0.0025 0 1.73472347597681E-18"
        rpy="0 0 0" />
      <mass
        value="0.0139800873084746" />
      <inertia
        ixx="6.9900436542373E-07"
        ixy="7.98179605279416E-40"
        ixz="3.19271842111766E-39"
        iyy="3.7862736460452E-07"
        iyz="2.37728261461855E-23"
        izz="3.7862736460452E-07" />
    </inertial>
    <visual>
      <origin
        xyz="0 0 0"
        rpy="0 0 0" />
      <geometry>
        <mesh
          filename="package://fullurdf2/meshes/sec18.STL" />
      </geometry>
      <material
        name="">
        <color
          rgba="0.537254901960784 0.349019607843137 0.337254901960784 1" />
      </material>
    </visual>
    <collision>
      <origin
        xyz="0 0 0"
        rpy="0 0 0" />
      <geometry>
        <mesh
          filename="package://fullurdf2/meshes/sec18.STL" />
      </geometry>
    </collision>
  </link>
  <joint
    name="joint18"
    type="revolute">
    <origin
      xyz="0.01 0 0"
      rpy="0 0 0" />
    <parent
      link="sec17" />
    <child
      link="sec18" />
    <axis
      xyz="0 0 1" />
	<dynamics damping="0.00001" friction="0.1"/>
    <limit
      lower="-1.571"
      upper="1.571"
      effort="100"
      velocity="500" />
  </joint>
  <link
    name="sec19">
    <inertial>
      <origin
        xyz="0.0025 0 1.73472347597681E-18"
        rpy="0 0 0" />
      <mass
        value="0.0139800873084746" />
      <inertia
        ixx="6.9900436542373E-07"
        ixy="7.98179605279416E-40"
        ixz="3.19271842111766E-39"
        iyy="3.7862736460452E-07"
        iyz="2.37728261461855E-23"
        izz="3.7862736460452E-07" />
    </inertial>
    <visual>
      <origin
        xyz="0 0 0"
        rpy="0 0 0" />
      <geometry>
        <mesh
          filename="package://fullurdf2/meshes/sec19.STL" />
      </geometry>
      <material
        name="">
        <color
          rgba="0.537254901960784 0.349019607843137 0.337254901960784 1" />
      </material>
    </visual>
    <collision>
      <origin
        xyz="0 0 0"
        rpy="0 0 0" />
      <geometry>
        <mesh
          filename="package://fullurdf2/meshes/sec19.STL" />
      </geometry>
    </collision>
  </link>
  <joint
    name="joint19"
    type="revolute">
    <origin
      xyz="0.01 0 0"
      rpy="0 0 0" />
    <parent
      link="sec18" />
    <child
      link="sec19" />
    <axis
      xyz="0 0 1" />
	<dynamics damping="0.00001" friction="0.1"/>
    <limit
      lower="-1.571"
      upper="1.571"
      effort="100"
      velocity="500" />
  </joint>
  <link
    name="sec20">
    <inertial>
      <origin
        xyz="0.0098619 -6.9389E-18 -1.7347E-18"
        rpy="0 0 0" />
      <mass
        value="0.057326" />
      <inertia
        ixx="2.9166E-06"
        ixy="1.131E-22"
        ixz="5.9669E-23"
        iyy="2.2417E-06"
        iyz="2.2527E-22"
        izz="2.2417E-06" />
    </inertial>
    <visual>
      <origin
        xyz="0 0 0"
        rpy="0 0 0" />
      <geometry>
        <mesh
          filename="package://fullurdf2/meshes/sec20.STL" />
      </geometry>
      <material
        name="">
        <color
          rgba="0.53725 0.34902 0.33725 1" />
      </material>
    </visual>
    <collision>
      <origin
        xyz="0 0 0"
        rpy="0 0 0" />
      <geometry>
        <mesh
          filename="package://fullurdf2/meshes/sec20.STL" />
      </geometry>
    </collision>
  </link>
  <joint
    name="joint20"
    type="revolute">
    <origin
      xyz="0.01 0 0"
      rpy="0 0 0" />
    <parent
      link="sec19" />
    <child
      link="sec20" />
    <axis
      xyz="0 0 1" />
	<dynamics damping="0.00001" friction="0.1"/>
    <limit
      lower="-1.571"
      upper="1.571"
      effort="100"
      velocity="500" />
  </joint>
  <link
    name="sec21">
    <inertial>
      <origin
        xyz="2.2768E-18 -0.005 0"
        rpy="0 0 0" />
      <mass
        value="0.0002" />
      <inertia
        ixx="3.3333E-09"
        ixy="1.7233E-26"
        ixz="3.031E-26"
        iyy="1.7333E-09"
        iyz="-8.3207E-26"
        izz="1.7333E-09" />
    </inertial>
    <visual>
      <origin
        xyz="0 0 0"
        rpy="0 0 0" />
      <geometry>
        <mesh
          filename="package://fullurdf2/meshes/sec21.STL" />
      </geometry>
      <material
        name="">
        <color
          rgba="0.79216 0.81961 0.93333 1" />
      </material>
    </visual>
    <collision>
      <origin
        xyz="0 0 0"
        rpy="0 0 0" />
      <geometry>
        <mesh
          filename="package://fullurdf2/meshes/sec21.STL" />
      </geometry>
    </collision>
  </link>
  <joint
    name="joint21"
    type="fixed">
    <origin
      xyz="-0.011 -0.005 0"
      rpy="1.571 0 0" />
    <parent
      link="base_link" />
    <child
      link="sec21" />
    <axis
      xyz="1 0 1" />
	<dynamics damping="0.00001" friction="0.1"/>
    <limit
      lower="-1.571"
      upper="1.571"
      effort="100"
      velocity="500" />
  </joint>
  <link
    name="sec22">
    <inertial>
      <origin
        xyz="-0.0025 3.46944695195361E-18 -1.73472347597681E-18"
        rpy="0 0 0" />
      <mass
        value="0.0139800873084746" />
      <inertia
        ixx="6.99004365423729E-07"
        ixy="4.04587000999357E-39"
        ixz="-9.81587660229593E-24"
        iyy="3.7862736460452E-07"
        iyz="-7.36190745172194E-24"
        izz="3.7862736460452E-07" />
    </inertial>
    <visual>
      <origin
        xyz="0 0 0"
        rpy="0 0 0" />
      <geometry>
        <mesh
          filename="package://fullurdf2/meshes/sec22.STL" />
      </geometry>
      <material
        name="">
        <color
          rgba="0.537254901960784 0.349019607843137 0.337254901960784 1" />
      </material>
    </visual>
    <collision>
      <origin
        xyz="0 0 0"
        rpy="0 0 0" />
      <geometry>
        <mesh
          filename="package://fullurdf2/meshes/sec22.STL" />
      </geometry>
    </collision>
  </link>
  <joint
    name="joint22"
    type="revolute">
    <origin
      xyz="-0.01 0 0"
      rpy="0 0 0" />
    <parent
      link="sec21" />
    <child
      link="sec22" />
    <axis
      xyz="0 0 1" />
	<dynamics damping="0.00001" friction="0.1"/>
    <limit
      lower="-1.571"
      upper="1.571"
      effort="100"
      velocity="500" />
  </joint>
  <link
    name="sec23">
    <inertial>
      <origin
        xyz="-0.0025 1.73472347597681E-18 -1.73472347597681E-18"
        rpy="0 0 0" />
      <mass
        value="0.0139800873084746" />
      <inertia
        ixx="6.99004365423729E-07"
        ixy="-2.45396915057397E-24"
        ixz="-9.81587660229592E-24"
        iyy="3.7862736460452E-07"
        iyz="-7.36190745172193E-24"
        izz="3.7862736460452E-07" />
    </inertial>
    <visual>
      <origin
        xyz="0 0 0"
        rpy="0 0 0" />
      <geometry>
        <mesh
          filename="package://fullurdf2/meshes/sec23.STL" />
      </geometry>
      <material
        name="">
        <color
          rgba="0.537254901960784 0.349019607843137 0.337254901960784 1" />
      </material>
    </visual>
    <collision>
      <origin
        xyz="0 0 0"
        rpy="0 0 0" />
      <geometry>
        <mesh
          filename="package://fullurdf2/meshes/sec23.STL" />
      </geometry>
    </collision>
  </link>
  <joint
    name="joint23"
    type="revolute">
    <origin
      xyz="-0.01 0 0"
      rpy="0 0 0" />
    <parent
      link="sec22" />
    <child
      link="sec23" />
    <axis
      xyz="0 0 1" />
	<dynamics damping="0.00001" friction="0.1"/>
    <limit
      lower="-1.571"
      upper="1.571"
      effort="100"
      velocity="500" />
  </joint>
  <link
    name="sec24">
    <inertial>
      <origin
        xyz="-0.0025 0 -1.73472347597681E-18"
        rpy="0 0 0" />
      <mass
        value="0.0139800873084746" />
      <inertia
        ixx="6.99004365423729E-07"
        ixy="-2.45396915057397E-24"
        ixz="-9.81587660229592E-24"
        iyy="3.7862736460452E-07"
        iyz="-7.36190745172193E-24"
        izz="3.7862736460452E-07" />
    </inertial>
    <visual>
      <origin
        xyz="0 0 0"
        rpy="0 0 0" />
      <geometry>
        <mesh
          filename="package://fullurdf2/meshes/sec24.STL" />
      </geometry>
      <material
        name="">
        <color
          rgba="0.537254901960784 0.349019607843137 0.337254901960784 1" />
      </material>
    </visual>
    <collision>
      <origin
        xyz="0 0 0"
        rpy="0 0 0" />
      <geometry>
        <mesh
          filename="package://fullurdf2/meshes/sec24.STL" />
      </geometry>
    </collision>
  </link>
  <joint
    name="joint24"
    type="revolute">
    <origin
      xyz="-0.01 0 0"
      rpy="0 0 0" />
    <parent
      link="sec23" />
    <child
      link="sec24" />
    <axis
      xyz="0 0 1" />
	<dynamics damping="0.00001" friction="0.1"/>
    <limit
      lower="-1.571"
      upper="1.571"
      effort="100"
      velocity="500" />
  </joint>
  <link
    name="sec25">
    <inertial>
      <origin
        xyz="-0.0025 0 -1.73472347597681E-18"
        rpy="0 0 0" />
      <mass
        value="0.0139800873084746" />
      <inertia
        ixx="6.99004365423729E-07"
        ixy="-2.45396915057397E-24"
        ixz="-9.81587660229592E-24"
        iyy="3.7862736460452E-07"
        iyz="-7.36190745172193E-24"
        izz="3.7862736460452E-07" />
    </inertial>
    <visual>
      <origin
        xyz="0 0 0"
        rpy="0 0 0" />
      <geometry>
        <mesh
          filename="package://fullurdf2/meshes/sec25.STL" />
      </geometry>
      <material
        name="">
        <color
          rgba="0.537254901960784 0.349019607843137 0.337254901960784 1" />
      </material>
    </visual>
    <collision>
      <origin
        xyz="0 0 0"
        rpy="0 0 0" />
      <geometry>
        <mesh
          filename="package://fullurdf2/meshes/sec25.STL" />
      </geometry>
    </collision>
  </link>
  <joint
    name="joint25"
    type="revolute">
    <origin
      xyz="-0.01 0 0"
      rpy="0 0 0" />
    <parent
      link="sec24" />
    <child
      link="sec25" />
    <axis
      xyz="0 0 1" />
	<dynamics damping="0.00001" friction="0.1"/>
    <limit
      lower="-1.571"
      upper="1.571"
      effort="100"
      velocity="500" />
  </joint>
  <link
    name="sec26">
    <inertial>
      <origin
        xyz="-0.0025 0 -1.73472347597681E-18"
        rpy="0 0 0" />
      <mass
        value="0.0139800873084746" />
      <inertia
        ixx="6.9900436542373E-07"
        ixy="0"
        ixz="7.98179605279416E-40"
        iyy="3.7862736460452E-07"
        iyz="4.14107294159359E-24"
        izz="3.7862736460452E-07" />
    </inertial>
    <visual>
      <origin
        xyz="0 0 0"
        rpy="0 0 0" />
      <geometry>
        <mesh
          filename="package://fullurdf2/meshes/sec26.STL" />
      </geometry>
      <material
        name="">
        <color
          rgba="0.537254901960784 0.349019607843137 0.337254901960784 1" />
      </material>
    </visual>
    <collision>
      <origin
        xyz="0 0 0"
        rpy="0 0 0" />
      <geometry>
        <mesh
          filename="package://fullurdf2/meshes/sec26.STL" />
      </geometry>
    </collision>
  </link>
  <joint
    name="joint26"
    type="revolute">
    <origin
      xyz="-0.01 0 0"
      rpy="0 0 0" />
    <parent
      link="sec25" />
    <child
      link="sec26" />
    <axis
      xyz="0 0 1" />
	<dynamics damping="0.00001" friction="0.1"/>
    <limit
      lower="-1.571"
      upper="1.571"
      effort="100"
      velocity="500" />
  </joint>
  <link
    name="sec27">
    <inertial>
      <origin
        xyz="-0.0025 0 -1.73472347597681E-18"
        rpy="0 0 0" />
      <mass
        value="0.0139800873084746" />
      <inertia
        ixx="6.9900436542373E-07"
        ixy="0"
        ixz="7.98179605279416E-40"
        iyy="3.7862736460452E-07"
        iyz="4.14107294159359E-24"
        izz="3.7862736460452E-07" />
    </inertial>
    <visual>
      <origin
        xyz="0 0 0"
        rpy="0 0 0" />
      <geometry>
        <mesh
          filename="package://fullurdf2/meshes/sec27.STL" />
      </geometry>
      <material
        name="">
        <color
          rgba="0.537254901960784 0.349019607843137 0.337254901960784 1" />
      </material>
    </visual>
    <collision>
      <origin
        xyz="0 0 0"
        rpy="0 0 0" />
      <geometry>
        <mesh
          filename="package://fullurdf2/meshes/sec27.STL" />
      </geometry>
    </collision>
  </link>
  <joint
    name="joint27"
    type="revolute">
    <origin
      xyz="-0.01 0 0"
      rpy="0 0 0" />
    <parent
      link="sec26" />
    <child
      link="sec27" />
    <axis
      xyz="0 0 1" />
	<dynamics damping="0.00001" friction="0.1"/>
    <limit
      lower="-1.571"
      upper="1.571"
      effort="100"
      velocity="500" />
  </joint>
  <link
    name="sec28">
    <inertial>
      <origin
        xyz="-0.0025 0 -1.73472347597681E-18"
        rpy="0 0 0" />
      <mass
        value="0.0139800873084746" />
      <inertia
        ixx="6.9900436542373E-07"
        ixy="0"
        ixz="7.98179605279416E-40"
        iyy="3.7862736460452E-07"
        iyz="4.14107294159359E-24"
        izz="3.7862736460452E-07" />
    </inertial>
    <visual>
      <origin
        xyz="0 0 0"
        rpy="0 0 0" />
      <geometry>
        <mesh
          filename="package://fullurdf2/meshes/sec28.STL" />
      </geometry>
      <material
        name="">
        <color
          rgba="0.537254901960784 0.349019607843137 0.337254901960784 1" />
      </material>
    </visual>
    <collision>
      <origin
        xyz="0 0 0"
        rpy="0 0 0" />
      <geometry>
        <mesh
          filename="package://fullurdf2/meshes/sec28.STL" />
      </geometry>
    </collision>
  </link>
  <joint
    name="joint28"
    type="revolute">
    <origin
      xyz="-0.01 0 0"
      rpy="0 0 0" />
    <parent
      link="sec27" />
    <child
      link="sec28" />
    <axis
      xyz="0 0 1" />
	<dynamics damping="0.00001" friction="0.1"/>
    <limit
      lower="-1.571"
      upper="1.571"
      effort="100"
      velocity="500" />
  </joint>
  <link
    name="sec29">
    <inertial>
      <origin
        xyz="-0.0025 0 -1.73472347597681E-18"
        rpy="0 0 0" />
      <mass
        value="0.0139800873084746" />
      <inertia
        ixx="6.9900436542373E-07"
        ixy="0"
        ixz="7.98179605279416E-40"
        iyy="3.7862736460452E-07"
        iyz="4.14107294159359E-24"
        izz="3.7862736460452E-07" />
    </inertial>
    <visual>
      <origin
        xyz="0 0 0"
        rpy="0 0 0" />
      <geometry>
        <mesh
          filename="package://fullurdf2/meshes/sec29.STL" />
      </geometry>
      <material
        name="">
        <color
          rgba="0.537254901960784 0.349019607843137 0.337254901960784 1" />
      </material>
    </visual>
    <collision>
      <origin
        xyz="0 0 0"
        rpy="0 0 0" />
      <geometry>
        <mesh
          filename="package://fullurdf2/meshes/sec29.STL" />
      </geometry>
    </collision>
  </link>
  <joint
    name="joint29"
    type="revolute">
    <origin
      xyz="-0.01 0 0"
      rpy="0 0 0" />
    <parent
      link="sec28" />
    <child
      link="sec29" />
    <axis
      xyz="0 0 1" />
	<dynamics damping="0.00001" friction="0.1"/>
    <limit
      lower="-1.571"
      upper="1.571"
      effort="100"
      velocity="500" />
  </joint>
  <link
    name="sec30">
    <inertial>
      <origin
        xyz="-0.0098619 1.7347E-18 1.5613E-17"
        rpy="0 0 0" />
      <mass
        value="0.057326" />
      <inertia
        ixx="2.9166E-06"
        ixy="-1.131E-22"
        ixz="1.542E-22"
        iyy="2.2417E-06"
        iyz="-6.3024E-23"
        izz="2.2417E-06" />
    </inertial>
    <visual>
      <origin
        xyz="0 0 0"
        rpy="0 0 0" />
      <geometry>
        <mesh
          filename="package://fullurdf2/meshes/sec30.STL" />
      </geometry>
      <material
        name="">
        <color
          rgba="0.53725 0.34902 0.33725 1" />
      </material>
    </visual>
    <collision>
      <origin
        xyz="0 0 0"
        rpy="0 0 0" />
      <geometry>
        <mesh
          filename="package://fullurdf2/meshes/sec30.STL" />
      </geometry>
    </collision>
  </link>
  <joint
    name="joint30"
    type="revolute">
    <origin
      xyz="-0.01 0 0"
      rpy="0 0 0" />
    <parent
      link="sec29" />
    <child
      link="sec30" />
    <axis
      xyz="0 0 1" />
	<dynamics damping="0.00001" friction="0.1"/>
    <limit
      lower="-1.571"
      upper="1.571"
      effort="100"
      velocity="500" />
  </joint>

  <gazebo>

  <plugin name="gazebo_ros_control" filename="libgazebo_ros_control.so">
  </plugin>

  </gazebo>

  <!--transmission definition -->
<!--<transmission name="tran01">
    <type>transmission_interface/SimpleTransmission</type>
    <joint name="joint01">
      <hardwareInterface>hardware_interface/EffortJointInterface</hardwareInterface>
    </joint>
    <actuator name="motor01">
      <hardwareInterface>hardware_interface/EffortJointInterface</hardwareInterface>
      <mechanicalReduction>1</mechanicalReduction>
    </actuator>
  </transmission>
  -->

  <transmission name="tran02">
    <type>transmission_interface/SimpleTransmission</type>
    <joint name="joint02">
      <hardwareInterface>hardware_interface/EffortJointInterface</hardwareInterface>
    </joint>
    <actuator name="motor02">
      <hardwareInterface>hardware_interface/EffortJointInterface</hardwareInterface>
      <mechanicalReduction>1</mechanicalReduction>
    </actuator>
  </transmission>
  
  <transmission name="tran03">
    <type>transmission_interface/SimpleTransmission</type>
    <joint name="joint03">
      <hardwareInterface>hardware_interface/EffortJointInterface</hardwareInterface>
    </joint>
    <actuator name="motor03">
      <hardwareInterface>hardware_interface/EffortJointInterface</hardwareInterface>
      <mechanicalReduction>1</mechanicalReduction>
    </actuator>
  </transmission>
  
  <transmission name="tran04">
    <type>transmission_interface/SimpleTransmission</type>
    <joint name="joint04">
      <hardwareInterface>hardware_interface/EffortJointInterface</hardwareInterface>
    </joint>
    <actuator name="motor04">
      <hardwareInterface>hardware_interface/EffortJointInterface</hardwareInterface>
      <mechanicalReduction>1</mechanicalReduction>
    </actuator>
  </transmission>
  
  <transmission name="tran05">
    <type>transmission_interface/SimpleTransmission</type>
    <joint name="joint05">
      <hardwareInterface>hardware_interface/EffortJointInterface</hardwareInterface>
    </joint>
    <actuator name="motor05">
      <hardwareInterface>hardware_interface/EffortJointInterface</hardwareInterface>
      <mechanicalReduction>1</mechanicalReduction>
    </actuator>
  </transmission>
  
  <transmission name="tran06">
    <type>transmission_interface/SimpleTransmission</type>
    <joint name="joint06">
      <hardwareInterface>hardware_interface/EffortJointInterface</hardwareInterface>
    </joint>
    <actuator name="motor06">
      <hardwareInterface>hardware_interface/EffortJointInterface</hardwareInterface>
      <mechanicalReduction>1</mechanicalReduction>
    </actuator>
  </transmission>
  
  <transmission name="tran07">
    <type>transmission_interface/SimpleTransmission</type>
    <joint name="joint07">
      <hardwareInterface>hardware_interface/EffortJointInterface</hardwareInterface>
    </joint>
    <actuator name="motor07">
      <hardwareInterface>hardware_interface/EffortJointInterface</hardwareInterface>
      <mechanicalReduction>1</mechanicalReduction>
    </actuator>
  </transmission>
  
  <transmission name="tran08">
    <type>transmission_interface/SimpleTransmission</type>
    <joint name="joint08">
      <hardwareInterface>hardware_interface/EffortJointInterface</hardwareInterface>
    </joint>
    <actuator name="motor08">
      <hardwareInterface>hardware_interface/EffortJointInterface</hardwareInterface>
      <mechanicalReduction>1</mechanicalReduction>
    </actuator>
  </transmission>

  <transmission name="tran09">
    <type>transmission_interface/SimpleTransmission</type>
    <joint name="joint09">
      <hardwareInterface>hardware_interface/EffortJointInterface</hardwareInterface>
    </joint>
    <actuator name="motor09">
      <hardwareInterface>hardware_interface/EffortJointInterface</hardwareInterface>
      <mechanicalReduction>1</mechanicalReduction>
    </actuator>
  </transmission>

  <transmission name="tran10">
    <type>transmission_interface/SimpleTransmission</type>
    <joint name="joint10">
      <hardwareInterface>hardware_interface/EffortJointInterface</hardwareInterface>
    </joint>
    <actuator name="motor10">
      <hardwareInterface>hardware_interface/EffortJointInterface</hardwareInterface>
      <mechanicalReduction>1</mechanicalReduction>
    </actuator>
  </transmission>

  <!--<transmission name="tran11">
    <type>transmission_interface/SimpleTransmission</type>
    <joint name="joint11">
      <hardwareInterface>hardware_interface/EffortJointInterface</hardwareInterface>
    </joint>
    <actuator name="motor11">
      <hardwareInterface>hardware_interface/EffortJointInterface</hardwareInterface>
      <mechanicalReduction>5</mechanicalReduction>
    </actuator>
  </transmission>
  -->

  <transmission name="tran12">
    <type>transmission_interface/SimpleTransmission</type>
    <joint name="joint12">
      <hardwareInterface>hardware_interface/EffortJointInterface</hardwareInterface>
    </joint>
    <actuator name="motor12">
      <hardwareInterface>hardware_interface/EffortJointInterface</hardwareInterface>
      <mechanicalReduction>5</mechanicalReduction>
    </actuator>
  </transmission>
  
  <transmission name="tran13">
    <type>transmission_interface/SimpleTransmission</type>
    <joint name="joint13">
      <hardwareInterface>hardware_interface/EffortJointInterface</hardwareInterface>
    </joint>
    <actuator name="motor13">
      <hardwareInterface>hardware_interface/EffortJointInterface</hardwareInterface>
      <mechanicalReduction>5</mechanicalReduction>
    </actuator>
  </transmission>
  
  <transmission name="tran14">
    <type>transmission_interface/SimpleTransmission</type>
    <joint name="joint14">
      <hardwareInterface>hardware_interface/EffortJointInterface</hardwareInterface>
    </joint>
    <actuator name="motor14">
      <hardwareInterface>hardware_interface/EffortJointInterface</hardwareInterface>
      <mechanicalReduction>5</mechanicalReduction>
    </actuator>
  </transmission>
  
  <transmission name="tran15">
    <type>transmission_interface/SimpleTransmission</type>
    <joint name="joint15">
      <hardwareInterface>hardware_interface/EffortJointInterface</hardwareInterface>
    </joint>
    <actuator name="motor15">
      <hardwareInterface>hardware_interface/EffortJointInterface</hardwareInterface>
      <mechanicalReduction>5</mechanicalReduction>
    </actuator>
  </transmission>
  
  <transmission name="tran16">
    <type>transmission_interface/SimpleTransmission</type>
    <joint name="joint16">
      <hardwareInterface>hardware_interface/EffortJointInterface</hardwareInterface>
    </joint>
    <actuator name="motor16">
      <hardwareInterface>hardware_interface/EffortJointInterface</hardwareInterface>
      <mechanicalReduction>5</mechanicalReduction>
    </actuator>
  </transmission>
  
  <transmission name="tran17">
    <type>transmission_interface/SimpleTransmission</type>
    <joint name="joint17">
      <hardwareInterface>hardware_interface/EffortJointInterface</hardwareInterface>
    </joint>
    <actuator name="motor17">
      <hardwareInterface>hardware_interface/EffortJointInterface</hardwareInterface>
      <mechanicalReduction>5</mechanicalReduction>
    </actuator>
  </transmission>
  
  <transmission name="tran18">
    <type>transmission_interface/SimpleTransmission</type>
    <joint name="joint18">
      <hardwareInterface>hardware_interface/EffortJointInterface</hardwareInterface>
    </joint>
    <actuator name="motor18">
      <hardwareInterface>hardware_interface/EffortJointInterface</hardwareInterface>
      <mechanicalReduction>5</mechanicalReduction>
    </actuator>
  </transmission>

  <transmission name="tran19">
    <type>transmission_interface/SimpleTransmission</type>
    <joint name="joint19">
      <hardwareInterface>hardware_interface/EffortJointInterface</hardwareInterface>
    </joint>
    <actuator name="motor19">
      <hardwareInterface>hardware_interface/EffortJointInterface</hardwareInterface>
      <mechanicalReduction>5</mechanicalReduction>
    </actuator>
  </transmission>

  <transmission name="tran20">
    <type>transmission_interface/SimpleTransmission</type>
    <joint name="joint20">
      <hardwareInterface>hardware_interface/EffortJointInterface</hardwareInterface>
    </joint>
    <actuator name="motor20">
      <hardwareInterface>hardware_interface/EffortJointInterface</hardwareInterface>
      <mechanicalReduction>5</mechanicalReduction>
    </actuator>
  </transmission>

<!--<transmission name="tran21">
    <type>transmission_interface/SimpleTransmission</type>
    <joint name="joint21">
      <hardwareInterface>hardware_interface/EffortJointInterface</hardwareInterface>
    </joint>
    <actuator name="motor21">
      <hardwareInterface>hardware_interface/EffortJointInterface</hardwareInterface>
      <mechanicalReduction>1</mechanicalReduction>
    </actuator>
  </transmission>-->
  
  <transmission name="tran22">
    <type>transmission_interface/SimpleTransmission</type>
    <joint name="joint22">
      <hardwareInterface>hardware_interface/EffortJointInterface</hardwareInterface>
    </joint>
    <actuator name="motor22">
      <hardwareInterface>hardware_interface/EffortJointInterface</hardwareInterface>
      <mechanicalReduction>1</mechanicalReduction>
    </actuator>
  </transmission>
  
  <transmission name="tran23">
    <type>transmission_interface/SimpleTransmission</type>
    <joint name="joint23">
      <hardwareInterface>hardware_interface/EffortJointInterface</hardwareInterface>
    </joint>
    <actuator name="motor23">
      <hardwareInterface>hardware_interface/EffortJointInterface</hardwareInterface>
      <mechanicalReduction>1</mechanicalReduction>
    </actuator>
  </transmission>
  
  <transmission name="tran24">
    <type>transmission_interface/SimpleTransmission</type>
    <joint name="joint24">
      <hardwareInterface>hardware_interface/EffortJointInterface</hardwareInterface>
    </joint>
    <actuator name="motor24">
      <hardwareInterface>hardware_interface/EffortJointInterface</hardwareInterface>
      <mechanicalReduction>1</mechanicalReduction>
    </actuator>
  </transmission>
  
  <transmission name="tran25">
    <type>transmission_interface/SimpleTransmission</type>
    <joint name="joint25">
      <hardwareInterface>hardware_interface/EffortJointInterface</hardwareInterface>
    </joint>
    <actuator name="motor25">
      <hardwareInterface>hardware_interface/EffortJointInterface</hardwareInterface>
      <mechanicalReduction>1</mechanicalReduction>
    </actuator>
  </transmission>
  
  <transmission name="tran26">
    <type>transmission_interface/SimpleTransmission</type>
    <joint name="joint26">
      <hardwareInterface>hardware_interface/EffortJointInterface</hardwareInterface>
    </joint>
    <actuator name="motor26">
      <hardwareInterface>hardware_interface/EffortJointInterface</hardwareInterface>
      <mechanicalReduction>1</mechanicalReduction>
    </actuator>
  </transmission>
  
  <transmission name="tran27">
    <type>transmission_interface/SimpleTransmission</type>
    <joint name="joint27">
      <hardwareInterface>hardware_interface/EffortJointInterface</hardwareInterface>
    </joint>
    <actuator name="motor27">
      <hardwareInterface>hardware_interface/EffortJointInterface</hardwareInterface>
      <mechanicalReduction>1</mechanicalReduction>
    </actuator>
  </transmission>
  
  <transmission name="tran28">
    <type>transmission_interface/SimpleTransmission</type>
    <joint name="joint28">
      <hardwareInterface>hardware_interface/EffortJointInterface</hardwareInterface>
    </joint>
    <actuator name="motor28">
      <hardwareInterface>hardware_interface/EffortJointInterface</hardwareInterface>
      <mechanicalReduction>1</mechanicalReduction>
    </actuator>
  </transmission>

  <transmission name="tran29">
    <type>transmission_interface/SimpleTransmission</type>
    <joint name="joint29">
      <hardwareInterface>hardware_interface/EffortJointInterface</hardwareInterface>
    </joint>
    <actuator name="motor29">
      <hardwareInterface>hardware_interface/EffortJointInterface</hardwareInterface>
      <mechanicalReduction>1</mechanicalReduction>
    </actuator>
  </transmission>

  <transmission name="tran30">
    <type>transmission_interface/SimpleTransmission</type>
    <joint name="joint30">
      <hardwareInterface>hardware_interface/EffortJointInterface</hardwareInterface>
    </joint>
    <actuator name="motor30">
      <hardwareInterface>hardware_interface/EffortJointInterface</hardwareInterface>
      <mechanicalReduction>1</mechanicalReduction>
    </actuator>
  </transmission>

<!--<transmission name="tran31">
    <type>transmission_interface/SimpleTransmission</type>
    <joint name="joint31">
      <hardwareInterface>hardware_interface/EffortJointInterface</hardwareInterface>
    </joint>
    <actuator name="motor31">
      <hardwareInterface>hardware_interface/EffortJointInterface</hardwareInterface>
      <mechanicalReduction>1</mechanicalReduction>
    </actuator>
  </transmission>-->
  
  <transmission name="tran32">
    <type>transmission_interface/SimpleTransmission</type>
    <joint name="joint32">
      <hardwareInterface>hardware_interface/EffortJointInterface</hardwareInterface>
    </joint>
    <actuator name="motor32">
      <hardwareInterface>hardware_interface/EffortJointInterface</hardwareInterface>
      <mechanicalReduction>1</mechanicalReduction>
    </actuator>
  </transmission>
  
  <transmission name="tran33">
    <type>transmission_interface/SimpleTransmission</type>
    <joint name="joint33">
      <hardwareInterface>hardware_interface/EffortJointInterface</hardwareInterface>
    </joint>
    <actuator name="motor33">
      <hardwareInterface>hardware_interface/EffortJointInterface</hardwareInterface>
      <mechanicalReduction>1</mechanicalReduction>
    </actuator>
  </transmission>
  
  <transmission name="tran34">
    <type>transmission_interface/SimpleTransmission</type>
    <joint name="joint34">
      <hardwareInterface>hardware_interface/EffortJointInterface</hardwareInterface>
    </joint>
    <actuator name="motor34">
      <hardwareInterface>hardware_interface/EffortJointInterface</hardwareInterface>
      <mechanicalReduction>1</mechanicalReduction>
    </actuator>
  </transmission>
  
  <transmission name="tran35">
    <type>transmission_interface/SimpleTransmission</type>
    <joint name="joint35">
      <hardwareInterface>hardware_interface/EffortJointInterface</hardwareInterface>
    </joint>
    <actuator name="motor35">
      <hardwareInterface>hardware_interface/EffortJointInterface</hardwareInterface>
      <mechanicalReduction>1</mechanicalReduction>
    </actuator>
  </transmission>
  
  <transmission name="tran36">
    <type>transmission_interface/SimpleTransmission</type>
    <joint name="joint36">
      <hardwareInterface>hardware_interface/EffortJointInterface</hardwareInterface>
    </joint>
    <actuator name="motor36">
      <hardwareInterface>hardware_interface/EffortJointInterface</hardwareInterface>
      <mechanicalReduction>1</mechanicalReduction>
    </actuator>
  </transmission>
  
  <transmission name="tran37">
    <type>transmission_interface/SimpleTransmission</type>
    <joint name="joint37">
      <hardwareInterface>hardware_interface/EffortJointInterface</hardwareInterface>
    </joint>
    <actuator name="motor37">
      <hardwareInterface>hardware_interface/EffortJointInterface</hardwareInterface>
      <mechanicalReduction>1</mechanicalReduction>
    </actuator>
  </transmission>
  
  <transmission name="tran38">
    <type>transmission_interface/SimpleTransmission</type>
    <joint name="joint38">
      <hardwareInterface>hardware_interface/EffortJointInterface</hardwareInterface>
    </joint>
    <actuator name="motor38">
      <hardwareInterface>hardware_interface/EffortJointInterface</hardwareInterface>
      <mechanicalReduction>1</mechanicalReduction>
    </actuator>
  </transmission>

  <transmission name="tran39">
    <type>transmission_interface/SimpleTransmission</type>
    <joint name="joint39">
      <hardwareInterface>hardware_interface/EffortJointInterface</hardwareInterface>
    </joint>
    <actuator name="motor39">
      <hardwareInterface>hardware_interface/EffortJointInterface</hardwareInterface>
      <mechanicalReduction>1</mechanicalReduction>
    </actuator>
  </transmission>

  <transmission name="tran40">
    <type>transmission_interface/SimpleTransmission</type>
    <joint name="joint40">
      <hardwareInterface>hardware_interface/EffortJointInterface</hardwareInterface>
    </joint>
    <actuator name="motor40">
      <hardwareInterface>hardware_interface/EffortJointInterface</hardwareInterface>
      <mechanicalReduction>1</mechanicalReduction>
    </actuator>
  </transmission>

<!--<transmission name="tran41">
    <type>transmission_interface/SimpleTransmission</type>
    <joint name="joint41">
      <hardwareInterface>hardware_interface/EffortJointInterface</hardwareInterface>
    </joint>
    <actuator name="motor41">
      <hardwareInterface>hardware_interface/EffortJointInterface</hardwareInterface>
      <mechanicalReduction>1</mechanicalReduction>
    </actuator>
  </transmission>-->
  
  <transmission name="tran42">
    <type>transmission_interface/SimpleTransmission</type>
    <joint name="joint42">
      <hardwareInterface>hardware_interface/EffortJointInterface</hardwareInterface>
    </joint>
    <actuator name="motor42">
      <hardwareInterface>hardware_interface/EffortJointInterface</hardwareInterface>
      <mechanicalReduction>1</mechanicalReduction>
    </actuator>
  </transmission>
  
  <transmission name="tran43">
    <type>transmission_interface/SimpleTransmission</type>
    <joint name="joint43">
      <hardwareInterface>hardware_interface/EffortJointInterface</hardwareInterface>
    </joint>
    <actuator name="motor43">
      <hardwareInterface>hardware_interface/EffortJointInterface</hardwareInterface>
      <mechanicalReduction>1</mechanicalReduction>
    </actuator>
  </transmission>
  
  <transmission name="tran44">
    <type>transmission_interface/SimpleTransmission</type>
    <joint name="joint44">
      <hardwareInterface>hardware_interface/EffortJointInterface</hardwareInterface>
    </joint>
    <actuator name="motor44">
      <hardwareInterface>hardware_interface/EffortJointInterface</hardwareInterface>
      <mechanicalReduction>1</mechanicalReduction>
    </actuator>
  </transmission>
  
  <transmission name="tran45">
    <type>transmission_interface/SimpleTransmission</type>
    <joint name="joint45">
      <hardwareInterface>hardware_interface/EffortJointInterface</hardwareInterface>
    </joint>
    <actuator name="motor45">
      <hardwareInterface>hardware_interface/EffortJointInterface</hardwareInterface>
      <mechanicalReduction>1</mechanicalReduction>
    </actuator>
  </transmission>
  
  <transmission name="tran46">
    <type>transmission_interface/SimpleTransmission</type>
    <joint name="joint46">
      <hardwareInterface>hardware_interface/EffortJointInterface</hardwareInterface>
    </joint>
    <actuator name="motor46">
      <hardwareInterface>hardware_interface/EffortJointInterface</hardwareInterface>
      <mechanicalReduction>1</mechanicalReduction>
    </actuator>
  </transmission>
  
  <transmission name="tran47">
    <type>transmission_interface/SimpleTransmission</type>
    <joint name="joint47">
      <hardwareInterface>hardware_interface/EffortJointInterface</hardwareInterface>
    </joint>
    <actuator name="motor47">
      <hardwareInterface>hardware_interface/EffortJointInterface</hardwareInterface>
      <mechanicalReduction>1</mechanicalReduction>
    </actuator>
  </transmission>
  
  <transmission name="tran48">
    <type>transmission_interface/SimpleTransmission</type>
    <joint name="joint48">
      <hardwareInterface>hardware_interface/EffortJointInterface</hardwareInterface>
    </joint>
    <actuator name="motor48">
      <hardwareInterface>hardware_interface/EffortJointInterface</hardwareInterface>
      <mechanicalReduction>1</mechanicalReduction>
    </actuator>
  </transmission>

  <transmission name="tran49">
    <type>transmission_interface/SimpleTransmission</type>
    <joint name="joint49">
      <hardwareInterface>hardware_interface/EffortJointInterface</hardwareInterface>
    </joint>
    <actuator name="motor49">
      <hardwareInterface>hardware_interface/EffortJointInterface</hardwareInterface>
      <mechanicalReduction>1</mechanicalReduction>
    </actuator>
  </transmission>

  <transmission name="tran50">
    <type>transmission_interface/SimpleTransmission</type>
    <joint name="joint50">
      <hardwareInterface>hardware_interface/EffortJointInterface</hardwareInterface>
    </joint>
    <actuator name="motor50">
      <hardwareInterface>hardware_interface/EffortJointInterface</hardwareInterface>
      <mechanicalReduction>1</mechanicalReduction>
    </actuator>
  </transmission>

  <gazebo>
  <plugin name="JointStiffnessPlugin" filename="libsoftactuator.so">
  <joint>
    <name>joint02</name>
    <stiffness>0.4</stiffness>
    <damping>1</damping>
    <friction>0.03</friction>
  </joint>
  <joint>
    <name>joint03</name>
    <stiffness>0.4</stiffness>
    <damping>1</damping>
    <friction>0.03</friction>
  </joint>
  <joint>
    <name>joint04</name>
    <stiffness>0.4</stiffness>
    <damping>1</damping>
    <friction>0.03</friction>
  </joint>
  <joint>
    <name>joint05</name>
    <stiffness>0.4</stiffness>
    <damping>1</damping>
    <friction>0.03</friction>
  </joint>
  <joint>
    <name>joint06</name>
    <stiffness>0.4</stiffness>
    <damping>1</damping>
    <friction>0.03</friction>
  </joint>
  <joint>
    <name>joint07</name>
    <stiffness>0.4</stiffness>
    <damping>1</damping>
    <friction>0.03</friction>
  </joint>

  <joint>
    <name>joint08</name>
    <stiffness>0.4</stiffness>
    <damping>1</damping>
    <friction>0.03</friction>
  </joint>

  <joint>
    <name>joint09</name>
    <stiffness>0.4</stiffness>
    <damping>1</damping>
    <friction>0.03</friction>
  </joint>

  <joint>
    <name>joint10</name>
    <stiffness>0.4</stiffness>
    <damping>1</damping>
    <friction>0.03</friction>
  </joint>

  <joint>
    <name>joint12</name>
    <stiffness>0.4</stiffness>
    <damping>1</damping>
    <friction>0.03</friction>
  </joint>

  <joint>
    <name>joint13</name>
    <stiffness>0.4</stiffness>
    <damping>1</damping>
    <friction>0.03</friction>
  </joint>

  <joint>
    <name>joint14</name>
    <stiffness>0.4</stiffness>
    <damping>1</damping>
    <friction>0.03</friction>
  </joint>

  <joint>
    <name>joint15</name>
    <stiffness>0.4</stiffness>
    <damping>1</damping>
    <friction>0.03</friction>
  </joint>

  <joint>
    <name>joint16</name>
    <stiffness>0.4</stiffness>
    <damping>1</damping>
    <friction>0.03</friction>
  </joint>

  <joint>
    <name>joint17</name>
    <stiffness>0.4</stiffness>
    <damping>1</damping>
    <friction>0.03</friction>
  </joint>

  <joint>
    <name>joint18</name>
    <stiffness>0.4</stiffness>
    <damping>1</damping>
    <friction>0.03</friction>
  </joint>

  <joint>
    <name>joint19</name>
    <stiffness>0.4</stiffness>
    <damping>1</damping>
    <friction>0.03</friction>
  </joint>

  <joint>
    <name>joint20</name>
    <stiffness>0.4</stiffness>
    <damping>1</damping>
    <friction>0.03</friction>
  </joint>

  <joint>
    <name>joint22</name>
    <stiffness>0.4</stiffness>
    <damping>1</damping>
    <friction>0.03</friction>
  </joint>

  <joint>
    <name>joint23</name>
    <stiffness>0.4</stiffness>
    <damping>1</damping>
    <friction>0.03</friction>
  </joint>

  <joint>
    <name>joint24</name>
    <stiffness>0.4</stiffness>
    <damping>1</damping>
    <friction>0.03</friction>
  </joint>

  <joint>
    <name>joint25</name>
    <stiffness>0.4</stiffness>
    <damping>1</damping>
    <friction>0.03</friction>
  </joint>

  <joint>
    <name>joint26</name>
    <stiffness>0.4</stiffness>
    <damping>1</damping>
    <friction>0.03</friction>
  </joint>

  <joint>
    <name>joint27</name>
    <stiffness>0.4</stiffness>
    <damping>1</damping>
    <friction>0.03</friction>
  </joint>

  <joint>
    <name>joint28</name>
    <stiffness>0.4</stiffness>
    <damping>1</damping>
    <friction>0.03</friction>
  </joint>

  <joint>
    <name>joint29</name>
    <stiffness>0.4</stiffness>
    <damping>1</damping>
    <friction>0.03</friction>
  </joint>

  <joint>
    <name>joint30</name>
    <stiffness>0.4</stiffness>
    <damping>1</damping>
    <friction>0.03</friction>
  </joint>

  <joint>
    <name>joint32</name>
    <stiffness>0.4</stiffness>
    <damping>1</damping>
    <friction>0.03</friction>
  </joint>

  <joint>
    <name>joint33</name>
    <stiffness>0.4</stiffness>
    <damping>1</damping>
    <friction>0.03</friction>
  </joint>

  <joint>
    <name>joint34</name>
    <stiffness>0.4</stiffness>
    <damping>1</damping>
    <friction>0.03</friction>
  </joint>

  <joint>
    <name>joint35</name>
    <stiffness>0.4</stiffness>
    <damping>1</damping>
    <friction>0.03</friction>
  </joint>

  <joint>
    <name>joint36</name>
    <stiffness>0.4</stiffness>
    <damping>1</damping>
    <friction>0.03</friction>
  </joint>

  <joint>
    <name>joint37</name>
    <stiffness>0.4</stiffness>
    <damping>1</damping>
    <friction>0.03</friction>
  </joint>

  <joint>
    <name>joint38</name>
    <stiffness>0.4</stiffness>
    <damping>1</damping>
    <friction>0.03</friction>
  </joint>

  <joint>
    <name>joint39</name>
    <stiffness>0.4</stiffness>
    <damping>1</damping>
    <friction>0.03</friction>
  </joint>

  <joint>
    <name>joint40</name>
    <stiffness>0.4</stiffness>
    <damping>1</damping>
    <friction>0.03</friction>
  </joint>

  <joint>
    <name>joint42</name>
    <stiffness>0.4</stiffness>
    <damping>1</damping>
    <friction>0.03</friction>
  </joint>

  <joint>
    <name>joint43</name>
    <stiffness>0.4</stiffness>
    <damping>1</damping>
    <friction>0.03</friction>
  </joint>

  <joint>
    <name>joint44</name>
    <stiffness>0.4</stiffness>
    <damping>1</damping>
    <friction>0.03</friction>
  </joint>

  <joint>
    <name>joint45</name>
    <stiffness>0.4</stiffness>
    <damping>1</damping>
    <friction>0.03</friction>
  </joint>

  <joint>
    <name>joint46</name>
    <stiffness>0.4</stiffness>
    <damping>1</damping>
    <friction>0.03</friction>
  </joint>

  <joint>
    <name>joint47</name>
    <stiffness>0.4</stiffness>
    <damping>1</damping>
    <friction>0.03</friction>
  </joint>

  <joint>
    <name>joint48</name>
    <stiffness>0.4</stiffness>
    <damping>1</damping>
    <friction>0.03</friction>
  </joint>

  <joint>
    <name>joint49</name>
    <stiffness>0.4</stiffness>
    <damping>1</damping>
    <friction>0.03</friction>
  </joint>

  <joint>
    <name>joint50</name>
    <stiffness>0.4</stiffness>
    <damping>1</damping>
    <friction>0.03</friction>
  </joint>

  </plugin>

  </gazebo>
</robot>