<?xml version="1.0" encoding="utf-8"?>
<!-- This URDF was automatically created by SolidWorks to URDF Exporter! Originally created by Stephen Brawner (brawner@gmail.com) 
     Commit Version: 1.6.0-1-g15f4949  Build Version: 1.6.7594.29634
     For more information, please see http://wiki.ros.org/sw_urdf_exporter -->
<robot
  name="softactuator">
  <link
    name="base_link">
    <inertial>
      <origin
        xyz="-1.2663E-17 0.0206 0.10996"
        rpy="0 1 0" />
      <mass
        value="3.6235" />
      <inertia
        ixx="0.15623"
        ixy="1.4868E-18"
        ixz="-4.0692E-17"
        iyy="0.15007"
        iyz="-0.016753"
        izz="0.046849" />
    </inertial>
    <visual>
      <origin
        xyz="0 0 0"
        rpy="0 0 0" />
      <geometry>
        <mesh
          filename="package://softactuator/meshes/base_link.STL" />
      </geometry>
      <material
        name="">
        <color
          rgba="0.79216 0.81961 0.93333 1" />
      </material>
    </visual>
    <collision>
      <origin
        xyz="0 0 0"
        rpy="0 0 0" />
      <geometry>
        <mesh
          filename="package://softactuator/meshes/base_link.STL" />
      </geometry>
    </collision>
  </link>
  <link
    name="sec01">
    <inertial>
      <origin
        xyz="9.10729824887824E-18 -3.46944695195361E-17 0.00475000000000003"
        rpy="0 0 0" />
      <mass
        value="0.0151090971683583" />
      <inertia
        ixx="2.02587811199071E-06"
        ixy="5.29395592033938E-23"
        ixz="3.34400831663348E-23"
        iyy="2.02587811199071E-06"
        iyz="-2.43179067269129E-24"
        izz="3.8244902207407E-06" />
    </inertial>
    <visual>
      <origin
        xyz="0 0 0"
        rpy="0 0 0" />
      <geometry>
        <mesh
          filename="package://softactuator/meshes/sec01.STL" />
      </geometry>
      <material
        name="">
        <color
          rgba="0.792156862745098 0.819607843137255 0.933333333333333 1" />
      </material>
    </visual>
    <collision>
      <origin
        xyz="0 0 0"
        rpy="0 0 0" />
      <geometry>
        <mesh
          filename="package://softactuator/meshes/sec01.STL" />
      </geometry>
    </collision>
  </link>
  <!--
    <link name="dummy" type="fixed"/>  
	<joint name="dummy_to_base_link=" type="fixed">  
	<origin
        xyz="0 0 0"
        rpy="0 0 0" />
    	<parent link="dummy"/>  
     	<child link="base_link"/>  
	</joint>
	-->

  <joint
    name="joint01"
    type="revolute">
    <origin
      xyz="0 -0.5825 -0.049051"
      rpy="1.5708 -0.072593 0" />
    <parent
      link="base_link" />
    <child
      link="sec01" />
    <axis
      xyz="0 0 1" />
      <!-- -->
    <limit
      lower="-1.57"
      upper="1.57"
      effort="100"
      velocity="500" />
  </joint>
  <link
    name="sec02">
    <inertial>
      <origin
        xyz="9.10729824887824E-18 -3.46944695195361E-17 -0.00475000000000003"
        rpy="0 0 0" />
      <mass
        value="0.0151090971683583" />
      <inertia
        ixx="2.02587811199071E-06"
        ixy="5.29395592033938E-23"
        ixz="3.34400831663348E-23"
        iyy="2.02587811199071E-06"
        iyz="-2.43179067269129E-24"
        izz="3.8244902207407E-06" />
    </inertial>
    <visual>
      <origin
        xyz="0 0 0"
        rpy="0 0 0" />
      <geometry>
        <mesh
          filename="package://softactuator/meshes/sec02.STL" />
      </geometry>
      <material
        name="">
        <color
          rgba="0.792156862745098 0.819607843137255 0.933333333333333 1" />
      </material>
    </visual>
    <collision>
      <origin
        xyz="0 0 0"
        rpy="0 0 0" />
      <geometry>
        <mesh
          filename="package://softactuator/meshes/sec02.STL" />
      </geometry>
    </collision>
  </link>
  <joint
    name="joint02"
    type="revolute">
    <origin
      xyz="0 0 -0.0205"
      rpy="0 0 0" />
    <parent
      link="sec01" />
    <child
      link="sec02" />
    <axis
      xyz="0 1 0" />
      <!-- -->
    <limit
      lower="-1.57"
      upper="1.57"
      effort="100"
      velocity="500" />
  </joint>
  <link
    name="sec03">
    <inertial>
      <origin
        xyz="9.10729824887824E-18 -3.46944695195361E-17 -0.00524999999999998"
        rpy="0 0 0" />
      <mass
        value="0.0151090971683583" />
      <inertia
        ixx="2.02587811199071E-06"
        ixy="5.29395592033938E-23"
        ixz="3.34400831663348E-23"
        iyy="2.02587811199071E-06"
        iyz="-2.43179067269129E-24"
        izz="3.8244902207407E-06" />
    </inertial>
    <visual>
      <origin
        xyz="0 0 0"
        rpy="0 0 0" />
      <geometry>
        <mesh
          filename="package://softactuator/meshes/sec03.STL" />
      </geometry>
      <material
        name="">
        <color
          rgba="0.792156862745098 0.819607843137255 0.933333333333333 1" />
      </material>
    </visual>
    <collision>
      <origin
        xyz="0 0 0"
        rpy="0 0 0" />
      <geometry>
        <mesh
          filename="package://softactuator/meshes/sec03.STL" />
      </geometry>
    </collision>
  </link>
  <joint
    name="joint03"
    type="revolute">
    <origin
      xyz="0 0 -0.0295"
      rpy="0 0 0" />
    <parent
      link="sec02" />
    <child
      link="sec03" />
    <axis
      xyz="0 1 0" />
      <!-- -->
    <limit
      lower="-1.57"
      upper="1.57"
      effort="100"
      velocity="500" />
  </joint>
  <link
    name="sec04">
    <inertial>
      <origin
        xyz="9.10729824887824E-18 -3.46944695195361E-17 -0.00474999999999998"
        rpy="0 0 0" />
      <mass
        value="0.0151090971683583" />
      <inertia
        ixx="2.02587811199071E-06"
        ixy="5.29395592033938E-23"
        ixz="-9.0526433996975E-39"
        iyy="2.02587811199071E-06"
        iyz="-2.17386507914307E-39"
        izz="3.8244902207407E-06" />
    </inertial>
    <visual>
      <origin
        xyz="0 0 0"
        rpy="0 0 0" />
      <geometry>
        <mesh
          filename="package://softactuator/meshes/sec04.STL" />
      </geometry>
      <material
        name="">
        <color
          rgba="0.792156862745098 0.819607843137255 0.933333333333333 1" />
      </material>
    </visual>
    <collision>
      <origin
        xyz="0 0 0"
        rpy="0 0 0" />
      <geometry>
        <mesh
          filename="package://softactuator/meshes/sec04.STL" />
      </geometry>
    </collision>
  </link>
  <joint
    name="joint04"
    type="revolute">
    <origin
      xyz="0 0 -0.0305"
      rpy="0 0 0" />
    <parent
      link="sec03" />
    <child
      link="sec04" />
    <axis
      xyz="0 1 0" />
      <!-- -->
    <limit
      lower="-1.57"
      upper="1.57"
      effort="100"
      velocity="500" />
  </joint>
  <link
    name="sec05">
    <inertial>
      <origin
        xyz="9.10729824887824E-18 -3.46944695195361E-17 -0.00475000000000003"
        rpy="0 0 0" />
      <mass
        value="0.0151090971683584" />
      <inertia
        ixx="2.02587811199073E-06"
        ixy="5.29395592033938E-23"
        ixz="1.80482279854177E-37"
        iyy="2.02587811199073E-06"
        iyz="-1.87114583269484E-38"
        izz="3.82449022074073E-06" />
    </inertial>
    <visual>
      <origin
        xyz="0 0 0"
        rpy="0 0 0" />
      <geometry>
        <mesh
          filename="package://softactuator/meshes/sec05.STL" />
      </geometry>
      <material
        name="">
        <color
          rgba="0.792156862745098 0.819607843137255 0.933333333333333 1" />
      </material>
    </visual>
    <collision>
      <origin
        xyz="0 0 0"
        rpy="0 0 0" />
      <geometry>
        <mesh
          filename="package://softactuator/meshes/sec05.STL" />
      </geometry>
    </collision>
  </link>
  <joint
    name="joint05"
    type="revolute">
    <origin
      xyz="0 0 -0.03"
      rpy="0 0 0" />
    <parent
      link="sec04" />
    <child
      link="sec05" />
    <axis
      xyz="0 1 0" />
      <!-- -->
    <limit
      lower="-1.57"
      upper="1.57"
      effort="100"
      velocity="500" />
  </joint>
  <link
    name="sec06">
    <inertial>
      <origin
        xyz="9.10729824887824E-18 -3.46944695195361E-17 -0.00474999999999992"
        rpy="0 0 0" />
      <mass
        value="0.0151090971683584" />
      <inertia
        ixx="2.02587811199073E-06"
        ixy="5.29395592033938E-23"
        ixz="-1.89755064553703E-37"
        iyy="2.02587811199073E-06"
        iyz="1.35103822887091E-38"
        izz="3.82449022074073E-06" />
    </inertial>
    <visual>
      <origin
        xyz="0 0 0"
        rpy="0 0 0" />
      <geometry>
        <mesh
          filename="package://softactuator/meshes/sec06.STL" />
      </geometry>
      <material
        name="">
        <color
          rgba="0.792156862745098 0.819607843137255 0.933333333333333 1" />
      </material>
    </visual>
    <collision>
      <origin
        xyz="0 0 0"
        rpy="0 0 0" />
      <geometry>
        <mesh
          filename="package://softactuator/meshes/sec06.STL" />
      </geometry>
    </collision>
  </link>
  <joint
    name="joint06"
    type="revolute">
    <origin
      xyz="0 0 -0.03"
      rpy="0 0 0" />
    <parent
      link="sec05" />
    <child
      link="sec06" />
    <axis
      xyz="0 1 0" />
      <!-- -->
    <limit
      lower="-1.57"
      upper="1.57"
      effort="100"
      velocity="500" />
  </joint>
  <link
    name="sec07">
    <inertial>
      <origin
        xyz="9.10729824887824E-18 -3.46944695195361E-17 -0.00474999999999992"
        rpy="0 0 0" />
      <mass
        value="0.0151090971683584" />
      <inertia
        ixx="2.02587811199073E-06"
        ixy="5.29395592033938E-23"
        ixz="-1.89755064553703E-37"
        iyy="2.02587811199073E-06"
        iyz="1.35103822887091E-38"
        izz="3.82449022074073E-06" />
    </inertial>
    <visual>
      <origin
        xyz="0 0 0"
        rpy="0 0 0" />
      <geometry>
        <mesh
          filename="package://softactuator/meshes/sec07.STL" />
      </geometry>
      <material
        name="">
        <color
          rgba="0.792156862745098 0.819607843137255 0.933333333333333 1" />
      </material>
    </visual>
    <collision>
      <origin
        xyz="0 0 0"
        rpy="0 0 0" />
      <geometry>
        <mesh
          filename="package://softactuator/meshes/sec07.STL" />
      </geometry>
    </collision>
  </link>
  <joint
    name="joint07"
    type="revolute">
    <origin
      xyz="0 0 -0.03"
      rpy="0 0 0" />
    <parent
      link="sec06" />
    <child
      link="sec07" />
    <axis
      xyz="0 1 0" />
      <!-- -->
    <limit
      lower="-1.57"
      upper="1.57"
      effort="100"
      velocity="500" />
  </joint>
  <link
    name="sec08">
    <inertial>
      <origin
        xyz="9.10729824887824E-18 -3.46944695195361E-17 -0.00474999999999992"
        rpy="0 0 0" />
      <mass
        value="0.0151090971683584" />
      <inertia
        ixx="2.02587811199073E-06"
        ixy="5.29395592033938E-23"
        ixz="-1.89755064553703E-37"
        iyy="2.02587811199073E-06"
        iyz="1.35103822887091E-38"
        izz="3.82449022074073E-06" />
    </inertial>
    <visual>
      <origin
        xyz="0 0 0"
        rpy="0 0 0" />
      <geometry>
        <mesh
          filename="package://softactuator/meshes/sec08.STL" />
      </geometry>
      <material
        name="">
        <color
          rgba="0.792156862745098 0.819607843137255 0.933333333333333 1" />
      </material>
    </visual>
    <collision>
      <origin
        xyz="0 0 0"
        rpy="0 0 0" />
      <geometry>
        <mesh
          filename="package://softactuator/meshes/sec08.STL" />
      </geometry>
    </collision>
  </link>
  <joint
    name="joint08"
    type="revolute">
    <origin
      xyz="0 0 -0.03"
      rpy="0 0 0" />
    <parent
      link="sec07" />
    <child
      link="sec08" />
    <axis
      xyz="0 1 0" />
      <!-- -->
    <limit
      lower="-1.57"
      upper="1.57"
      effort="100"
      velocity="500" />
  </joint>
  <link
    name="sec09">
    <inertial>
      <origin
        xyz="9.10729824887824E-18 -3.46944695195361E-17 -0.00474999999999998"
        rpy="0 0 0" />
      <mass
        value="0.0151090971683584" />
      <inertia
        ixx="2.02587811199073E-06"
        ixy="5.29395592033938E-23"
        ixz="1.80482279854177E-37"
        iyy="2.02587811199073E-06"
        iyz="-1.87114583269484E-38"
        izz="3.82449022074073E-06" />
    </inertial>
    <visual>
      <origin
        xyz="0 0 0"
        rpy="0 0 0" />
      <geometry>
        <mesh
          filename="package://softactuator/meshes/sec09.STL" />
      </geometry>
      <material
        name="">
        <color
          rgba="0.792156862745098 0.819607843137255 0.933333333333333 1" />
      </material>
    </visual>
    <collision>
      <origin
        xyz="0 0 0"
        rpy="0 0 0" />
      <geometry>
        <mesh
          filename="package://softactuator/meshes/sec09.STL" />
      </geometry>
    </collision>
  </link>
  <joint
    name="joint09"
    type="revolute">
    <origin
      xyz="0 0 -0.03"
      rpy="0 0 0" />
    <parent
      link="sec08" />
    <child
      link="sec09" />
    <axis
      xyz="0 1 0" />
      <!-- -->
    <limit
      lower="-1.57"
      upper="1.57"
      effort="100"
      velocity="500" />
  </joint>
  <link
    name="sec10">
    <inertial>
      <origin
        xyz="9.10729824887824E-18 -3.46944695195361E-17 -0.00474999999999992"
        rpy="0 0 0" />
      <mass
        value="0.0151090971683584" />
      <inertia
        ixx="2.02587811199073E-06"
        ixy="5.29395592033938E-23"
        ixz="-1.89755064553703E-37"
        iyy="2.02587811199073E-06"
        iyz="1.35103822887091E-38"
        izz="3.82449022074073E-06" />
    </inertial>
    <visual>
      <origin
        xyz="0 0 0"
        rpy="0 0 0" />
      <geometry>
        <mesh
          filename="package://softactuator/meshes/sec10.STL" />
      </geometry>
      <material
        name="">
        <color
          rgba="0.792156862745098 0.819607843137255 0.933333333333333 1" />
      </material>
    </visual>
    <collision>
      <origin
        xyz="0 0 0"
        rpy="0 0 0" />
      <geometry>
        <mesh
          filename="package://softactuator/meshes/sec10.STL" />
      </geometry>
    </collision>
  </link>
  <joint
    name="joint10"
    type="revolute">
    <origin
      xyz="0 0 -0.03"
      rpy="0 0 0" />
    <parent
      link="sec09" />
    <child
      link="sec10" />
    <axis
      xyz="0 1 0" />
      <!-- -->
    <limit
      lower="-1.57"
      upper="1.57"
      effort="100"
      velocity="500" />
  </joint>
  <link
    name="sec11">
    <inertial>
      <origin
        xyz="9.10729824887824E-18 -3.46944695195361E-17 -0.00474999999999992"
        rpy="0 0 0" />
      <mass
        value="0.0151090971683584" />
      <inertia
        ixx="2.02587811199073E-06"
        ixy="5.29395592033938E-23"
        ixz="-1.89755064553703E-37"
        iyy="2.02587811199073E-06"
        iyz="1.35103822887091E-38"
        izz="3.82449022074073E-06" />
    </inertial>
    <visual>
      <origin
        xyz="0 0 0"
        rpy="0 0 0" />
      <geometry>
        <mesh
          filename="package://softactuator/meshes/sec11.STL" />
      </geometry>
      <material
        name="">
        <color
          rgba="0.792156862745098 0.819607843137255 0.933333333333333 1" />
      </material>
    </visual>
    <collision>
      <origin
        xyz="0 0 0"
        rpy="0 0 0" />
      <geometry>
        <mesh
          filename="package://softactuator/meshes/sec11.STL" />
      </geometry>
    </collision>
  </link>
  <joint
    name="joint11"
    type="revolute">
    <origin
      xyz="0 0 -0.03"
      rpy="0 0 0" />
    <parent
      link="sec10" />
    <child
      link="sec11" />
    <axis
      xyz="0 1 0" />
      <!-- -->
    <limit
      lower="-1.57"
      upper="1.57"
      effort="100"
      velocity="500" />
  </joint>
    
  

<!--transmission definition -->
<transmission name="tran01">
    <type>transmission_interface/SimpleTransmission</type>
    <joint name="joint01">
      <hardwareInterface>hardware_interface/EffortJointInterface</hardwareInterface>
    </joint>
    <actuator name="motor01">
      <hardwareInterface>hardware_interface/EffortJointInterface</hardwareInterface>
      <mechanicalReduction>1</mechanicalReduction>
    </actuator>
  </transmission>
  
  <transmission name="tran02">
    <type>transmission_interface/SimpleTransmission</type>
    <joint name="joint02">
      <hardwareInterface>hardware_interface/EffortJointInterface</hardwareInterface>
    </joint>
    <actuator name="motor02">
      <hardwareInterface>hardware_interface/EffortJointInterface</hardwareInterface>
      <mechanicalReduction>1</mechanicalReduction>
    </actuator>
  </transmission>
  
  <transmission name="tran03">
    <type>transmission_interface/SimpleTransmission</type>
    <joint name="joint03">
      <hardwareInterface>hardware_interface/EffortJointInterface</hardwareInterface>
    </joint>
    <actuator name="motor03">
      <hardwareInterface>hardware_interface/EffortJointInterface</hardwareInterface>
      <mechanicalReduction>1</mechanicalReduction>
    </actuator>
  </transmission>
  
  <transmission name="tran04">
    <type>transmission_interface/SimpleTransmission</type>
    <joint name="joint04">
      <hardwareInterface>hardware_interface/EffortJointInterface</hardwareInterface>
    </joint>
    <actuator name="motor04">
      <hardwareInterface>hardware_interface/EffortJointInterface</hardwareInterface>
      <mechanicalReduction>1</mechanicalReduction>
    </actuator>
  </transmission>
  
  <transmission name="tran05">
    <type>transmission_interface/SimpleTransmission</type>
    <joint name="joint05">
      <hardwareInterface>hardware_interface/EffortJointInterface</hardwareInterface>
    </joint>
    <actuator name="motor05">
      <hardwareInterface>hardware_interface/EffortJointInterface</hardwareInterface>
      <mechanicalReduction>1</mechanicalReduction>
    </actuator>
  </transmission>
  
  <transmission name="tran06">
    <type>transmission_interface/SimpleTransmission</type>
    <joint name="joint06">
      <hardwareInterface>hardware_interface/EffortJointInterface</hardwareInterface>
    </joint>
    <actuator name="motor06">
      <hardwareInterface>hardware_interface/EffortJointInterface</hardwareInterface>
      <mechanicalReduction>1</mechanicalReduction>
    </actuator>
  </transmission>
  
  <transmission name="tran07">
    <type>transmission_interface/SimpleTransmission</type>
    <joint name="joint07">
      <hardwareInterface>hardware_interface/EffortJointInterface</hardwareInterface>
    </joint>
    <actuator name="motor07">
      <hardwareInterface>hardware_interface/EffortJointInterface</hardwareInterface>
      <mechanicalReduction>1</mechanicalReduction>
    </actuator>
  </transmission>
  
  <transmission name="tran08">
    <type>transmission_interface/SimpleTransmission</type>
    <joint name="joint08">
      <hardwareInterface>hardware_interface/EffortJointInterface</hardwareInterface>
    </joint>
    <actuator name="motor08">
      <hardwareInterface>hardware_interface/EffortJointInterface</hardwareInterface>
      <mechanicalReduction>1</mechanicalReduction>
    </actuator>
  </transmission>
  
  <transmission name="tran09">
    <type>transmission_interface/SimpleTransmission</type>
    <joint name="joint09">
      <hardwareInterface>hardware_interface/EffortJointInterface</hardwareInterface>
    </joint>
    <actuator name="motor09">
      <hardwareInterface>hardware_interface/EffortJointInterface</hardwareInterface>
      <mechanicalReduction>1</mechanicalReduction>
    </actuator>
  </transmission>
  
  <transmission name="tran10">
    <type>transmission_interface/SimpleTransmission</type>
    <joint name="joint10">
      <hardwareInterface>hardware_interface/EffortJointInterface</hardwareInterface>
    </joint>
    <actuator name="motor10">
      <hardwareInterface>hardware_interface/EffortJointInterface</hardwareInterface>
      <mechanicalReduction>1</mechanicalReduction>
    </actuator>
  </transmission>
  
  <transmission name="tran11">
    <type>transmission_interface/SimpleTransmission</type>
    <joint name="joint11">
      <hardwareInterface>hardware_interface/EffortJointInterface</hardwareInterface>
    </joint>
    <actuator name="motor11">
      <hardwareInterface>hardware_interface/EffortJointInterface</hardwareInterface>
      <mechanicalReduction>1</mechanicalReduction>
    </actuator>
  </transmission>
  
      <!--cointrol pluging -->
  <gazebo>
  <plugin name="gazebo_ros_control" filename="libgazebo_ros_control.so">

  </plugin>
</gazebo>

<!--
<gazebo reference="sec01">
   <turnGravityOff>true</turnGravityOff>
</gazebo>

<gazebo reference="sec02">
   <turnGravityOff>true</turnGravityOff>
</gazebo>

<gazebo reference="sec03">
   <turnGravityOff>true</turnGravityOff>
</gazebo>

<gazebo reference="sec04">
   <turnGravityOff>true</turnGravityOff>
</gazebo>

<gazebo reference="sec05">
   <turnGravityOff>true</turnGravityOff>
</gazebo>

<gazebo reference="sec06">
   <turnGravityOff>true</turnGravityOff>
</gazebo>

<gazebo reference="sec07">
   <turnGravityOff>true</turnGravityOff>
</gazebo>

<gazebo reference="sec08">
   <turnGravityOff>true</turnGravityOff>
</gazebo>

<gazebo reference="sec09">
   <turnGravityOff>true</turnGravityOff>
</gazebo>

<gazebo reference="sec10">
   <turnGravityOff>true</turnGravityOff>
</gazebo>

<gazebo reference="sec11">
   <turnGravityOff>true</turnGravityOff>
</gazebo>

-->

<!--
<gazebo>
    <plugin name="JointStiffnessPlugin" filename="libsoftactuator.so">
      <joint_name>joint01</joint_name>
      <stiffness>1.11</stiffness>
      <damping>2.8</damping>
    </plugin>
    </gazebo>

    <gazebo>
    <plugin name="JointStiffnessPlugin" filename="libsoftactuator.so">
      <joint_name>joint02</joint_name>
      <stiffness>1.11</stiffness>
      <damping>2.8</damping>
    </plugin>
    </gazebo>

    <gazebo>
    <plugin name="JointStiffnessPlugin" filename="libsoftactuator.so">
      <joint_name>joint03</joint_name>
      <stiffness>1.11</stiffness>
      <damping>2.8</damping>
    </plugin>
    </gazebo>

    <gazebo>
    <plugin name="JointStiffnessPlugin" filename="libsoftactuator.so">
      <joint_name>joint04</joint_name>
      <stiffness>1.11</stiffness>
      <damping>2.8</damping>
    </plugin>
    </gazebo>

    <gazebo>
    <plugin name="JointStiffnessPlugin" filename="libsoftactuator.so">
      <joint_name>joint05</joint_name>
      <stiffness>1.11</stiffness>
      <damping>2.8</damping>
    </plugin>
    </gazebo>

    <gazebo>
    <plugin name="JointStiffnessPlugin" filename="libsoftactuator.so">
      <joint_name>joint06</joint_name>
      <stiffness>1.11</stiffness>
      <damping>2.8</damping>
    </plugin>
    </gazebo>

    <gazebo>
    <plugin name="JointStiffnessPlugin" filename="libsoftactuator.so">
      <joint_name>joint07</joint_name>
      <stiffness>1.11</stiffness>
      <damping>2.8</damping>
    </plugin>
    </gazebo>

    <gazebo>
    <plugin name="JointStiffnessPlugin" filename="libsoftactuator.so">
      <joint_name>joint08</joint_name>
      <stiffness>1.11</stiffness>
      <damping>2.8</damping>
    </plugin>
    </gazebo>

    <gazebo>
    <plugin name="JointStiffnessPlugin" filename="libsoftactuator.so">
      <joint_name>joint09</joint_name>
      <stiffness>1.11</stiffness>
      <damping>2.8</damping>
    </plugin>
    </gazebo>

    <gazebo>
    <plugin name="JointStiffnessPlugin" filename="libsoftactuator.so">
      <joint_name>joint10</joint_name>
      <stiffness>1.11</stiffness>
      <damping>2.8</damping>
    </plugin>
    </gazebo>

    <gazebo>
    <plugin name="JointStiffnessPlugin" filename="libsoftactuator.so">
      <joint_name>joint11</joint_name>
      <stiffness>1.11</stiffness>
      <damping>2.8</damping>
    </plugin>
    </gazebo>-->

    <!--
      <gazebo>
  <plugin name="JointStiffnessPlugin" filename="libsoftactuator.so">
      <joint_name>joint02</joint_name>
      <stiffness>1.11</stiffness>
      <damping>2.8</damping>
       
      <joint_name>joint03</joint_name>
      <stiffness>1.11</stiffness>
      <damping>2.8</damping>
    
      <joint_name>joint04</joint_name>
      <stiffness>1.11</stiffness>
      <damping>2.8</damping>

      <joint_name>joint05</joint_name>
      <stiffness>1.11</stiffness>
      <damping>2.8</damping>

      <joint_name>joint06</joint_name>
      <stiffness>1.11</stiffness>
      <damping>2.8</damping>

      <joint_name>joint07</joint_name>
      <stiffness>1.11</stiffness>
      <damping>2.8</damping>

      <joint_name>joint08</joint_name>
      <stiffness>1.11</stiffness>
      <damping>2.8</damping>

      <joint_name>joint09</joint_name>
      <stiffness>1.11</stiffness>
      <damping>2.8</damping>

      <joint_name>joint10</joint_name>
      <stiffness>1.11</stiffness>
      <damping>2.8</damping>

      <joint_name>joint11</joint_name>
      <stiffness>1.11</stiffness>
      <damping>2.8</damping>
    </plugin>
</gazebo>-->
  


<gazebo>
  <plugin name="JointStiffnessPlugin" filename="libsoftactuator.so">
  <joint>
    <name>joint02</name>
    <stiffness>1.11</stiffness>
    <damping>2.8</damping>
    <friction>0.03</friction>
  </joint>
  <joint>
    <name>joint03</name>
    <stiffness>1.11</stiffness>
    <damping>2.8</damping>
    <friction>0.03</friction>
  </joint>
  <joint>
    <name>joint04</name>
    <stiffness>1.11</stiffness>
    <damping>2.8</damping>
    <friction>0.03</friction>
  </joint>
  <joint>
    <name>joint05</name>
    <stiffness>1.11</stiffness>
    <damping>2.8</damping>
    <friction>0.03</friction>
  </joint>
  <joint>
    <name>joint06</name>
    <stiffness>1.11</stiffness>
    <damping>2.8</damping>
    <friction>0.03</friction>
  </joint>
  <joint>
    <name>joint07</name>
    <stiffness>1.11</stiffness>
    <damping>2.8</damping>
    <friction>0.03</friction>
  </joint>

  <joint>
    <name>joint08</name>
    <stiffness>1.11</stiffness>
    <damping>2.8</damping>
    <friction>0.03</friction>
  </joint>

  <joint>
    <name>joint09</name>
    <stiffness>1.11</stiffness>
    <damping>2.8</damping>
    <friction>0.03</friction>
  </joint>

  <joint>
    <name>joint10</name>
    <stiffness>1.11</stiffness>
    <damping>2.8</damping>
    <friction>0.03</friction>
  </joint>

  <joint>
    <name>joint11</name>
    <stiffness>1.11</stiffness>
    <damping>2.8</damping>
    <friction>0.03</friction>
  </joint>
  </plugin>
</gazebo>


</robot>
